Workbook

Sheet 2023.10
A1: 장르 | B1: 개수 | V1: 내가만든유즈맵 | W1: 타인제작유즈맵 | X1: 맞히기 | Y1: 총 개수
A2: 맞히기 | B2: =VLOOKUP(A2,$U$2:$Y$26,5,0) -> 64 | U2: 캠페인 | V2: 9 | W2: 0 | Y2: =V2+W2+X2 -> 9
A3: 디펜스 | B3: =VLOOKUP(A3,$U$2:$Y$26,5,0) -> 16 | U3: 디펜스 | V3: 15 | W3: 1 | Y3: =V3+W3+X3 -> 16
A4: 컴까기 | B4: =VLOOKUP(A4,$U$2:$Y$26,5,0) -> 11 | U4: 대전 | V4: 6 | W4: 1 | Y4: =V4+W4+X4 -> 7
A5: 캠페인 | B5: =VLOOKUP(A5,$U$2:$Y$26,5,0) -> 9 | U5: RPG | V5: 8 | W5: 0 | Y5: =V5+W5+X5 -> 8
A6: 컨트롤 | B6: =VLOOKUP(A6,$U$2:$Y$26,5,0) -> 8 | U6: 블러드 | V6: 3 | W6: 0 | Y6: =V6+W6+X6 -> 3
A7: RPG | B7: =VLOOKUP(A7,$U$2:$Y$26,5,0) -> 8 | U7: 미니게임 | V7: 1 | W7: 0 | Y7: =V7+W7+X7 -> 1
A8: 대전 | B8: =VLOOKUP(A8,$U$2:$Y$26,5,0) -> 7 | U8: 컴까기 | V8: 10 | W8: 1 | Y8: =V8+W8+X8 -> 11
A9: 서바이벌 | B9: =VLOOKUP(A9,$U$2:$Y$26,5,0) -> 4 | U9: 서바이벌 | V9: 4 | W9: 0 | Y9: =V9+W9+X9 -> 4
A10: 기타 | B10: =VLOOKUP(A10,$U$2:$Y$26,5,0) -> 3 | U10: 컨트롤 | V10: 7 | W10: 1 | Y10: =V10+W10+X10 -> 8
A11: 블러드 | B11: =VLOOKUP(A11,$U$2:$Y$26,5,0) -> 3 | U11: 리듬게임 | V11: 1 | W11: 0 | Y11: =V11+W11+X11 -> 1
A12: 어드벤처 | B12: =VLOOKUP(A12,$U$2:$Y$26,5,0) -> 3 | U12: 퍼즐 | V12: 1 | W12: 0 | Y12: =V12+W12+X12 -> 1
A13: 디플로메시 | B13: =VLOOKUP(A13,$U$2:$Y$26,5,0) -> 3 | U13: 밀리기반 | V13: 2 | W13: 0 | Y13: =V13+W13+X13 -> 2
... A25: 병맛 | B25: =VLOOKUP(A25,$U$2:$Y$26,5,0) -> 0 | U25: AOS | V25: 1 | W25: 1 | Y25: =V25+W25+X25 -> 2
A26: 영상 | B26: =VLOOKUP(A26,$U$2:$Y$26,5,0) -> 0 | U26: 맞히기 | V26: 0 | W26: 0 | X26: 64 | Y26: =V26+W26+X26 -> 64

Sheet 2023.11
A1: 장르 | B1: 개수 | V1: 내가만든유즈맵 | W1: 타인제작유즈맵 | X1: 맞히기 | Y1: 총 개수
A2: 맞히기 | B2: =VLOOKUP(A2,$U$2:$Y$26,5,0) -> 36 | U2: 캠페인 | V2: 12 | W2: 0 | Y2: =V2+W2+X2 -> 12
A3: 디펜스 | B3: =VLOOKUP(A3,$U$2:$Y$26,5,0) -> 13 | U3: 디펜스 | V3: 10 | W3: 3 | Y3: =V3+W3+X3 -> 13
A4: 캠페인 | B4: =VLOOKUP(A4,$U$2:$Y$26,5,0) -> 12 | U4: 대전 | V4: 5 | W4: 1 | Y4: =V4+W4+X4 -> 6
A5: 컴까기 | B5: =VLOOKUP(A5,$U$2:$Y$26,5,0) -> 11 | U5: RPG | V5: 1 | W5: 1 | Y5: =V5+W5+X5 -> 2
A6: 컨트롤 | B6: =VLOOKUP(A6,$U$2:$Y$26,5,0) -> 6 | U6: 블러드 | V6: 2 | W6: 1 | Y6: =V6+W6+X6 -> 3
A7: 대전 | B7: =VLOOKUP(A7,$U$2:$Y$26,5,0) -> 6 | U7: 미니게임 | V7: 4 | W7: 0 | Y7: =V7+W7+X7 -> 4
A8: 서바이벌 | B8: =VLOOKUP(A8,$U$2:$Y$26,5,0) -> 5 | U8: 컴까기 | V8: 11 | W8: 0 | Y8: =V8+W8+X8 -> 11
A9: 기타 | B9: =VLOOKUP(A9,$U$2:$Y$26,5,0) -> 5 | U9: 서바이벌 | V9: 4 | W9: 1 | Y9: =V9+W9+X9 -> 5
A10: 미니게임 | B10: =VLOOKUP(A10,$U$2:$Y$26,5,0) -> 4 | U10: 컨트롤 | V10: 6 | W10: 0 | Y10: =V10+W10+X10 -> 6
A11: 블러드 | B11: =VLOOKUP(A11,$U$2:$Y$26,5,0) -> 3 | U11: 리듬게임 | V11: 0 | W11: 0 | Y11: =V11+W11+X11 -> 0
A12: 어드벤처 | B12: =VLOOKUP(A12,$U$2:$Y$26,5,0) -> 3 | U12: 퍼즐 | V12: 1 | W12: 0 | Y12: =V12+W12+X12 -> 1
A13: 디플로메시 | B13: =VLOOKUP(A13,$U$2:$Y$26,5,0) -> 3 | U13: 밀리기반 | V13: 3 | W13: 0 | Y13: =V13+W13+X13 -> 3
... A25: 병맛 | B25: =VLOOKUP(A25,$U$2:$Y$26,5,0) -> 0 | U25: AOS | V25: 0 | W25: 0 | Y25: =V25+W25+X25 -> 0
A26: 영상 | B26: =VLOOKUP(A26,$U$2:$Y$26,5,0) -> 0 | U26: 맞히기 | V26: 0 | W26: 0 | X26: 36 | Y26: =V26+W26+X26 -> 36

Sheet 2023.12
A1: 장르 | B1: 개수 | V1: 내가만든유즈맵 | W1: 타인제작유즈맵 | X1: 맞히기 | Y1: 총 개수
A2: 맞히기 | B2: =VLOOKUP(A2,$U$2:$Y$26,5,0) -> 37 | U2: 캠페인 | V2: 3 | W2: 4 | Y2: =V2+W2+X2 -> 7
A3: 디펜스 | B3: =VLOOKUP(A3,$U$2:$Y$26,5,0) -> 17 | U3: 디펜스 | V3: 16 | W3: 1 | Y3: =V3+W3+X3 -> 17
A4: 대전 | B4: =VLOOKUP(A4,$U$2:$Y$26,5,0) -> 13 | U4: 대전 | V4: 7 | W4: 6 | Y4: =V4+W4+X4 -> 13
A5: 컴까기 | B5: =VLOOKUP(A5,$U$2:$Y$26,5,0) -> 12 | U5: RPG | V5: 2 | W5: 4 | Y5: =V5+W5+X5 -> 6
A6: 컨트롤 | B6: =VLOOKUP(A6,$U$2:$Y$26,5,0) -> 11 | U6: 블러드 | V6: 0 | W6: 0 | Y6: =V6+W6+X6 -> 0
A7: 캠페인 | B7: =VLOOKUP(A7,$U$2:$Y$26,5,0) -> 7 | U7: 미니게임 | V7: 4 | W7: 1 | Y7: =V7+W7+X7 -> 5
A8: RPG | B8: =VLOOKUP(A8,$U$2:$Y$26,5,0) -> 6 | U8: 컴까기 | V8: 10 | W8: 2 | Y8: =V8+W8+X8 -> 12
A9: 미니게임 | B9: =VLOOKUP(A9,$U$2:$Y$26,5,0) -> 5 | U9: 서바이벌 | V9: 3 | W9: 0 | Y9: =V9+W9+X9 -> 3
A10: 서바이벌 | B10: =VLOOKUP(A10,$U$2:$Y$26,5,0) -> 3 | U10: 컨트롤 | V10: 11 | W10: 0 | Y10: =V10+W10+X10 -> 11
A11: 기타 | B11: =VLOOKUP(A11,$U$2:$Y$26,5,0) -> 3 | U11: 리듬게임 | V11: 0 | W11: 0 | Y11: =V11+W11+X11 -> 0
A12: 어드벤처 | B12: =VLOOKUP(A12,$U$2:$Y$26,5,0) -> 3 | U12: 퍼즐 | V12: 1 | W12: 0 | Y12: =V12+W12+X12 -> 1
A13: 키우기 | B13: =VLOOKUP(A13,$U$2:$Y$26,5,0) -> 3 | U13: 밀리기반 | V13: 2 | W13: 0 | Y13: =V13+W13+X13 -> 2
... A26: 영상 | B26: =VLOOKUP(A26,$U$2:$Y$26,5,0) -> 0 | U26: 맞히기 | V26: 0 | W26: 37 | Y26: =V26+W26+X26 -> 37

Sheet 2024.01
A1: 장르 | B1: 개수 | V1: 내가만든유즈맵 | W1: 타인제작유즈맵 | X1: 맞히기 | Y1: 총 개수
A2: 맞히기 | B2: =VLOOKUP(A2,$U$2:$Y$26,5,0) -> 47 | U2: 캠페인 | V2: 3 | W2: 4 | X2: 0 | Y2: =V2+W2+X2 -> 7
A3: 컨트롤 | B3: =VLOOKUP(A3,$U$2:$Y$26,5,0) -> 12 | U3: 디펜스 | V3: 11 | W3: 0 | X3: 0 | Y3: =V3+W3+X3 -> 11
A4: 디펜스 | B4: =VLOOKUP(A4,$U$2:$Y$26,5,0) -> 11 | U4: 대전 | V4: 3 | W4: 4 | X4: 0 | Y4: =V4+W4+X4 -> 7
A5: 기타 | B5: =VLOOKUP(A5,$U$2:$Y$26,5,0) -> 10 | U5: RPG | V5: 4 | W5: 2 | X5: 0 | Y5: =V5+W5+X5 -> 6
A6: 컴까기 | B6: =VLOOKUP(A6,$U$2:$Y$26,5,0) -> 8 | U6: 블러드 | V6: 1 | W6: 0 | X6: 0 | Y6: =V6+W6+X6 -> 1
A7: 대전 | B7: =VLOOKUP(A7,$U$2:$Y$26,5,0) -> 7 | U7: 미니게임 | V7: 5 | W7: 1 | X7: 0 | Y7: =V7+W7+X7 -> 6
A8: 캠페인 | B8: =VLOOKUP(A8,$U$2:$Y$26,5,0) -> 7 | U8: 컴까기 | V8: 7 | W8: 1 | X8: 0 | Y8: =V8+W8+X8 -> 8
A9: RPG | B9: =VLOOKUP(A9,$U$2:$Y$26,5,0) -> 6 | U9: 서바이벌 | V9: 5 | W9: 0 | X9: 0 | Y9: =V9+W9+X9 -> 5
A10: 미니게임 | B10: =VLOOKUP(A10,$U$2:$Y$26,5,0) -> 6 | U10: 컨트롤 | V10: 12 | W10: 0 | X10: 0 | Y10: =V10+W10+X10 -> 12
A11: 서바이벌 | B11: =VLOOKUP(A11,$U$2:$Y$26,5,0) -> 5 | U11: 리듬게임 | V11: 2 | W11: 0 | X11: 0 | Y11: =V11+W11+X11 -> 2
A12: 밀리기반 | B12: =VLOOKUP(A12,$U$2:$Y$26,5,0) -> 2 | U12: 퍼즐 | V12: 1 | W12: 0 | X12: 0 | Y12: =V12+W12+X12 -> 1
A13: 공포 | B13: =VLOOKUP(A13,$U$2:$Y$26,5,0) -> 2 | U13: 밀리기반 | V13: 2 | W13: 0 | X13: 0 | Y13: =V13+W13+X13 -> 2
... A26: 영상 | B26: =VLOOKUP(A26,$U$2:$Y$26,5,0) -> 0 | U26: 맞히기 | V26: 0 | W26: 0 | X26: 47 | Y26: =V26+W26+X26 -> 47

Sheet 2024.02
A1: 장르 | B1: 개수 | V1: 내가만든유즈맵 | W1: 타인제작유즈맵 | X1: 맞히기 | Y1: 총 개수
A2: 맞히기 | B2: =VLOOKUP(A2,$U$2:$Y$26,5,0) -> 29 | U2: 캠페인 | V2: 2 | W2: 3 | X2: 0 | Y2: =V2+W2+X2 -> 5
A3: 디펜스 | B3: =VLOOKUP(A3,$U$2:$Y$26,5,0) -> 13 | U3: 디펜스 | V3: 13 | W3: 0 | X3: 0 | Y3: =V3+W3+X3 -> 13
A4: 대전 | B4: =VLOOKUP(A4,$U$2:$Y$26,5,0) -> 10 | U4: 대전 | V4: 9 | W4: 1 | X4: 0 | Y4: =V4+W4+X4 -> 10
A5: 컨트롤 | B5: =VLOOKUP(A5,$U$2:$Y$26,5,0) -> 8 | U5: RPG | V5: 2 | W5: 4 | X5: 0 | Y5: =V5+W5+X5 -> 6
A6: 서바이벌 | B6: =VLOOKUP(A6,$U$2:$Y$26,5,0) -> 8 | U6: 블러드 | V6: 1 | W6: 1 | X6: 0 | Y6: =V6+W6+X6 -> 2
A7: 기타 | B7: =VLOOKUP(A7,$U$2:$Y$26,5,0) -> 7 | U7: 미니게임 | V7: 3 | W7: 1 | X7: 0 | Y7: =V7+W7+X7 -> 4
A8: RPG | B8: =VLOOKUP(A8,$U$2:$Y$26,5,0) -> 6 | U8: 컴까기 | V8: 5 | W8: 0 | X8: 0 | Y8: =V8+W8+X8 -> 5
A9: 밀리기반 | B9: =VLOOKUP(A9,$U$2:$Y$26,5,0) -> 6 | U9: 서바이벌 | V9: 8 | W9: 0 | X9: 0 | Y9: =V9+W9+X9 -> 8
A10: 컴까기 | B10: =VLOOKUP(A10,$U$2:$Y$26,5,0) -> 5 | U10: 컨트롤 | V10: 8 | W10: 0 | X10: 0 | Y10: =V10+W10+X10 -> 8
A11: 캠페인 | B11: =VLOOKUP(A11,$U$2:$Y$26,5,0) -> 5 | U11: 리듬게임 | V11: 0 | W11: 0 | X11: 0 | Y11: =V11+W11+X11 -> 0
A12: 미니게임 | B12: =VLOOKUP(A12,$U$2:$Y$26,5,0) -> 4 | U12: 퍼즐 | V12: 1 | W12: 1 | X12: 0 | Y12: =V12+W12+X12 -> 2
A13: 퍼즐 | B13: =VLOOKUP(A13,$U$2:$Y$26,5,0) -> 2 | U13: 밀리기반 | V13: 6 | W13: 0 | X13: 0 | Y13: =V13+W13+X13 -> 6
... A26: 영상 | B26: =VLOOKUP(A26,$U$2:$Y$26,5,0) -> 0 | U26: 맞히기 | V26: 0 | W26: 0 | X26: 29 | Y26: =V26+W26+X26 -> 29

Sheet 2024.03
A1: 장르 | B1: 개수 | V1: 내가만든유즈맵 | W1: 타인제작유즈맵 | X1: 맞히기 | Y1: 총 개수
A2: 맞히기 | B2: =VLOOKUP(A2,$U$2:$Y$26,5,0) -> 57 | U2: 캠페인 | V2: 14 | W2: 0 | X2: 0 | Y2: =V2+W2+X2 -> 14
A3: 대전 | B3: =VLOOKUP(A3,$U$2:$Y$26,5,0) -> 21 | U3: 디펜스 | V3: 13 | W3: 2 | X3: 0 | Y3: =V3+W3+X3 -> 15
A4: 디펜스 | B4: =VLOOKUP(A4,$U$2:$Y$26,5,0) -> 15 | U4: 대전 | V4: 14 | W4: 7 | X4: 0 | Y4: =V4+W4+X4 -> 21
A5: 캠페인 | B5: =VLOOKUP(A5,$U$2:$Y$26,5,0) -> 14 | U5: RPG | V5: 6 | W5: 2 | X5: 0 | Y5: =V5+W5+X5 -> 8
A6: 컴까기 | B6: =VLOOKUP(A6,$U$2:$Y$26,5,0) -> 13 | U6: 블러드 | V6: 1 | W6: 2 | X6: 0 | Y6: =V6+W6+X6 -> 3
A7: 디플로메시 | B7: =VLOOKUP(A7,$U$2:$Y$26,5,0) -> 9 | U7: 미니게임 | V7: 4 | W7: 0 | X7: 0 | Y7: =V7+W7+X7 -> 4
A8: RPG | B8: =VLOOKUP(A8,$U$2:$Y$26,5,0) -> 8 | U8: 컴까기 | V8: 13 | W8: 0 | X8: 0 | Y8: =V8+W8+X8 -> 13
A9: 기타 | B9: =VLOOKUP(A9,$U$2:$Y$26,5,0) -> 6 | U9: 서바이벌 | V9: 3 | W9: 0 | X9: 0 | Y9: =V9+W9+X9 -> 3
A10: 컨트롤 | B10: =VLOOKUP(A10,$U$2:$Y$26,5,0) -> 4 | U10: 컨트롤 | V10: 4 | W10: 0 | X10: 0 | Y10: =V10+W10+X10 -> 4
A11: 미니게임 | B11: =VLOOKUP(A11,$U$2:$Y$26,5,0) -> 4 | U11: 리듬게임 | V11: 0 | W11: 0 | X11: 0 | Y11: =V11+W11+X11 -> 0
A12: 서바이벌 | B12: =VLOOKUP(A12,$U$2:$Y$26,5,0) -> 3 | U12: 퍼즐 | V12: 1 | W12: 0 | X12: 0 | Y12: =V12+W12+X12 -> 1
A13: 블러드 | B13: =VLOOKUP(A13,$U$2:$Y$26,5,0) -> 3 | U13: 밀리기반 | V13: 2 | W13: 0 | X13: 0 | Y13: =V13+W13+X13 -> 2
... A26: 영상 | B26: =VLOOKUP(A26,$U$2:$Y$26,5,0) -> 0 | U26: 맞히기 | V26: 0 | W26: 0 | X26: 57 | Y26: =V26+W26+X26 -> 57

Sheet 2024.04
A1: 장르 | B1: 개수 | V1: 내가만든유즈맵 | W1: 타인제작유즈맵 | X1: 맞히기 | Y1: 총 개수
A2: 맞히기 | B2: =VLOOKUP(A2,$U$2:$Y$26,5,0) -> 41 | U2: 캠페인 | V2: 5 | W2: 1 | Y2: =V2+W2+X2 -> 6
A3: 디펜스 | B3: =VLOOKUP(A3,$U$2:$Y$26,5,0) -> 20 | U3: 디펜스 | V3: 16 | W3: 4 | Y3: =V3+W3+X3 -> 20
A4: RPG | B4: =VLOOKUP(A4,$U$2:$Y$26,5,0) -> 12 | U4: 대전 | V4: 5 | W4: 3 | Y4: =V4+W4+X4 -> 8
A5: 컴까기 | B5: =VLOOKUP(A5,$U$2:$Y$26,5,0) -> 11 | U5: RPG | V5: 8 | W5: 4 | Y5: =V5+W5+X5 -> 12
A6: 대전 | B6: =VLOOKUP(A6,$U$2:$Y$26,5,0) -> 8 | U6: 블러드 | V6: 4 | W6: 2 | Y6: =V6+W6+X6 -> 6
A7: 기타 | B7: =VLOOKUP(A7,$U$2:$Y$26,5,0) -> 7 | U7: 미니게임 | V7: 5 | W7: 2 | Y7: =V7+W7+X7 -> 7
A8: 미니게임 | B8: =VLOOKUP(A8,$U$2:$Y$26,5,0) -> 7 | U8: 컴까기 | V8: 11 | W8: 0 | Y8: =V8+W8+X8 -> 11
A9: 캠페인 | B9: =VLOOKUP(A9,$U$2:$Y$26,5,0) -> 6 | U9: 서바이벌 | V9: 2 | W9: 0 | Y9: =V9+W9+X9 -> 2
A10: 블러드 | B10: =VLOOKUP(A10,$U$2:$Y$26,5,0) -> 6 | U10: 컨트롤 | V10: 4 | W10: 0 | Y10: =V10+W10+X10 -> 4
A11: 컨트롤 | B11: =VLOOKUP(A11,$U$2:$Y$26,5,0) -> 4 | U11: 리듬게임 | V11: 1 | W11: 0 | Y11: =V11+W11+X11 -> 1
A12: 디플로메시 | B12: =VLOOKUP(A12,$U$2:$Y$26,5,0) -> 3 | U12: 퍼즐 | V12: 2 | W12: 0 | Y12: =V12+W12+X12 -> 2
A13: 키우기 | B13: =VLOOKUP(A13,$U$2:$Y$26,5,0) -> 3 | U13: 밀리기반 | V13: 1 | W13: 0 | Y13: =V13+W13+X13 -> 1
... A25: 병맛 | B25: =VLOOKUP(A25,$U$2:$Y$26,5,0) -> 0 | U25: AOS | V25: 0 | W25: 0 | Y25: =V25+W25+X25 -> 0
A26: 영상 | B26: =VLOOKUP(A26,$U$2:$Y$26,5,0) -> 0 | U26: 맞히기 | V26: 0 | W26: 0 | X26: 41 | Y26: =V26+W26+X26 -> 41

Sheet 2024.05
A1: 장르 | B1: 개수 | V1: 내가만든유즈맵 | W1: 타인제작유즈맵 | X1: 맞히기 | Y1: 총 개수
A2: 맞히기 | B2: =VLOOKUP(A2,$U$2:$Y$27,5,0) -> 49 | U2: 캠페인 | V2: 0 | W2: 8 | Y2: =V2+W2+X2 -> 8
A3: 디펜스 | B3: =VLOOKUP(A3,$U$2:$Y$27,5,0) -> 21 | U3: 디펜스 | V3: 19 | W3: 2 | Y3: =V3+W3+X3 -> 21
A4: 컴까기 | B4: =VLOOKUP(A4,$U$2:$Y$27,5,0) -> 14 | U4: 대전 | V4: 12 | W4: 1 | Y4: =V4+W4+X4 -> 13
A5: 대전 | B5: =VLOOKUP(A5,$U$2:$Y$27,5,0) -> 13 | U5: RPG | V5: 8 | W5: 2 | Y5: =V5+W5+X5 -> 10
A6: RPG | B6: =VLOOKUP(A6,$U$2:$Y$27,5,0) -> 10 | U6: 블러드 | V6: 4 | W6: 0 | Y6: =V6+W6+X6 -> 4
A7: 미니게임 | B7: =VLOOKUP(A7,$U$2:$Y$27,5,0) -> 9 | U7: 미니게임 | V7: 9 | W7: 0 | Y7: =V7+W7+X7 -> 9
A8: 캠페인 | B8: =VLOOKUP(A8,$U$2:$Y$27,5,0) -> 8 | U8: 컴까기 | V8: 14 | W8: 0 | Y8: =V8+W8+X8 -> 14
A9: 컨트롤 | B9: =VLOOKUP(A9,$U$2:$Y$27,5,0) -> 7 | U9: 서바이벌 | V9: 2 | W9: 0 | Y9: =V9+W9+X9 -> 2
A10: 공포 | B10: =VLOOKUP(A10,$U$2:$Y$27,5,0) -> 5 | U10: 컨트롤 | V10: 7 | W10: 0 | Y10: =V10+W10+X10 -> 7
A11: 블러드 | B11: =VLOOKUP(A11,$U$2:$Y$27,5,0) -> 4 | U11: 리듬게임 | V11: 1 | W11: 0 | Y11: =V11+W11+X11 -> 1
A12: 디플로메시 | B12: =VLOOKUP(A12,$U$2:$Y$27,5,0) -> 4 | U12: 퍼즐 | V12: 2 | W12: 0 | Y12: =V12+W12+X12 -> 2
A13: 어드벤처 | B13: =VLOOKUP(A13,$U$2:$Y$27,5,0) -> 4 | U13: 밀리기반 | V13: 0 | W13: 0 | Y13: =V13+W13+X13 -> 0
... A26: 병맛 | B26: =VLOOKUP(A26,$U$2:$Y$27,5,0) -> 0 | U26: 호환요청 | V26: 0 | W26: 2 | Y26: =V26+W26+X26 -> 2
A27: 영상 | B27: =VLOOKUP(A27,$U$2:$Y$27,5,0) -> 0 | U27: 맞히기 | V27: 0 | W27: 0 | X27: 49 | Y27: =V27+W27+X27 -> 49

Sheet 2024.06
A1: 장르 | B1: 개수 | V1: 내가만든유즈맵 | W1: 타인제작유즈맵 | X1: 맞히기 | Y1: 총 개수
A2: 맞히기 | B2: =VLOOKUP(A2,$U$2:$Y$27,5,0) -> 41 | U2: 캠페인 | V2: 4 | W2: 0 | Y2: =V2+W2+X2 -> 4
A3: 컴까기 | B3: =VLOOKUP(A3,$U$2:$Y$27,5,0) -> 25 | U3: 디펜스 | V3: 7 | W3: 1 | Y3: =V3+W3+X3 -> 8
A4: 컨트롤 | B4: =VLOOKUP(A4,$U$2:$Y$27,5,0) -> 14 | U4: 대전 | V4: 12 | W4: 1 | Y4: =V4+W4+X4 -> 13
A5: 대전 | B5: =VLOOKUP(A5,$U$2:$Y$27,5,0) -> 13 | U5: RPG | V5: 11 | W5: 2 | Y5: =V5+W5+X5 -> 13
A6: RPG | B6: =VLOOKUP(A6,$U$2:$Y$27,5,0) -> 13 | U6: 블러드 | V6: 5 | W6: 1 | Y6: =V6+W6+X6 -> 6
A7: 디펜스 | B7: =VLOOKUP(A7,$U$2:$Y$27,5,0) -> 8 | U7: 미니게임 | V7: 6 | W7: 0 | Y7: =V7+W7+X7 -> 6
A8: 미니게임 | B8: =VLOOKUP(A8,$U$2:$Y$27,5,0) -> 6 | U8: 컴까기 | V8: 23 | W8: 2 | Y8: =V8+W8+X8 -> 25
A9: 블러드 | B9: =VLOOKUP(A9,$U$2:$Y$27,5,0) -> 6 | U9: 서바이벌 | V9: 1 | W9: 0 | Y9: =V9+W9+X9 -> 1
A10: 디플로메시 | B10: =VLOOKUP(A10,$U$2:$Y$27,5,0) -> 5 | U10: 컨트롤 | V10: 13 | W10: 1 | Y10: =V10+W10+X10 -> 14
A11: 기타 | B11: =VLOOKUP(A11,$U$2:$Y$27,5,0) -> 5 | U11: 리듬게임 | V11: 0 | W11: 0 | Y11: =V11+W11+X11 -> 0
A12: 캠페인 | B12: =VLOOKUP(A12,$U$2:$Y$27,5,0) -> 4 | U12: 퍼즐 | V12: 1 | W12: 0 | Y12: =V12+W12+X12 -> 1
A13: 어드벤처 | B13: =VLOOKUP(A13,$U$2:$Y$27,5,0) -> 3 | U13: 밀리기반 | V13: 2 | W13: 0 | Y13: =V13+W13+X13 -> 2
... A26: 병맛 | B26: =VLOOKUP(A26,$U$2:$Y$27,5,0) -> 0 | U26: 호환요청 | V26: 0 | W26: 2 | Y26: =V26+W26+X26 -> 2
A27: 영상 | B27: =VLOOKUP(A27,$U$2:$Y$27,5,0) -> 0 | U27: 맞히기 | V27: 0 | W27: 0 | X27: 41 | Y27: =V27+W27+X27 -> 41

Sheet 2024.07
A1: 장르 | B1: 개수 | V1: 내가만든유즈맵 | W1: 타인제작유즈맵 | X1: 맞히기 | Y1: 총 개수
A2: 맞히기 | B2: =VLOOKUP(A2,$U$2:$Y$27,5,0) -> 48 | U2: 캠페인 | V2: 9 | W2: 0 | Y2: =V2+W2+X2 -> 9
A3: 컴까기 | B3: =VLOOKUP(A3,$U$2:$Y$27,5,0) -> 20 | U3: 디펜스 | V3: 6 | W3: 0 | Y3: =V3+W3+X3 -> 6
A4: 대전 | B4: =VLOOKUP(A4,$U$2:$Y$27,5,0) -> 14 | U4: 대전 | V4: 11 | W4: 3 | Y4: =V4+W4+X4 -> 14
A5: 키우기 | B5: =VLOOKUP(A5,$U$2:$Y$27,5,0) -> 10 | U5: RPG | V5: 4 | W5: 2 | Y5: =V5+W5+X5 -> 6
A6: 캠페인 | B6: =VLOOKUP(A6,$U$2:$Y$27,5,0) -> 9 | U6: 블러드 | V6: 2 | W6: 1 | Y6: =V6+W6+X6 -> 3
A7: 컨트롤 | B7: =VLOOKUP(A7,$U$2:$Y$27,5,0) -> 8 | U7: 미니게임 | V7: 6 | W7: 0 | Y7: =V7+W7+X7 -> 6
A8: RPG | B8: =VLOOKUP(A8,$U$2:$Y$27,5,0) -> 6 | U8: 컴까기 | V8: 20 | W8: 0 | Y8: =V8+W8+X8 -> 20
A9: 디펜스 | B9: =VLOOKUP(A9,$U$2:$Y$27,5,0) -> 6 | U9: 서바이벌 | V9: 2 | W9: 0 | Y9: =V9+W9+X9 -> 2
A10: 미니게임 | B10: =VLOOKUP(A10,$U$2:$Y$27,5,0) -> 6 | U10: 컨트롤 | V10: 7 | W10: 1 | Y10: =V10+W10+X10 -> 8
A11: 디플로메시 | B11: =VLOOKUP(A11,$U$2:$Y$27,5,0) -> 6 | U11: 리듬게임 | V11: 0 | W11: 0 | Y11: =V11+W11+X11 -> 0
A12: 어드벤처 | B12: =VLOOKUP(A12,$U$2:$Y$27,5,0) -> 6 | U12: 퍼즐 | V12: 0 | W12: 0 | Y12: =V12+W12+X12 -> 0
A13: 호환요청 | B13: =VLOOKUP(A13,$U$2:$Y$27,5,0) -> 4 | U13: 밀리기반 | V13: 0 | W13: 0 | Y13: =V13+W13+X13 -> 0
... A26: 병맛 | B26: =VLOOKUP(A26,$U$2:$Y$27,5,0) -> 0 | U26: 호환요청 | V26: 0 | W26: 4 | Y26: =V26+W26+X26 -> 4
A27: 영상 | B27: =VLOOKUP(A27,$U$2:$Y$27,5,0) -> 0 | U27: 맞히기 | V27: 0 | W27: 0 | X27: 48 | Y27: =V27+W27+X27 -> 48

Sheet 2024.08
A1: 장르 | B1: 개수 | V1: 내가만든유즈맵 | W1: 타인제작유즈맵 | X1: 맞히기 | Y1: 총 개수
A2: 맞히기 | B2: =VLOOKUP(A2,$U$2:$Y$28,5,0) -> 61 | U2: 캠페인 | V2: 8 | W2: 0 | Y2: =V2+W2+X2 -> 8
A3: 대전 | B3: =VLOOKUP(A3,$U$2:$Y$28,5,0) -> 15 | U3: 디펜스 | V3: 9 | W3: 1 | Y3: =V3+W3+X3 -> 10
A4: 컴까기 | B4: =VLOOKUP(A4,$U$2:$Y$28,5,0) -> 13 | U4: 대전 | V4: 9 | W4: 6 | Y4: =V4+W4+X4 -> 15
A5: 키우기 | B5: =VLOOKUP(A5,$U$2:$Y$28,5,0) -> 10 | U5: RPG | V5: 4 | W5: 5 | Y5: =V5+W5+X5 -> 9
A6: 디펜스 | B6: =VLOOKUP(A6,$U$2:$Y$28,5,0) -> 10 | U6: 블러드 | V6: 3 | W6: 0 | Y6: =V6+W6+X6 -> 3
A7: RPG | B7: =VLOOKUP(A7,$U$2:$Y$28,5,0) -> 9 | U7: 미니게임 | V7: 6 | W7: 0 | Y7: =V7+W7+X7 -> 6
A8: 호환요청 | B8: =VLOOKUP(A8,$U$2:$Y$28,5,0) -> 9 | U8: 컴까기 | V8: 13 | W8: 0 | Y8: =V8+W8+X8 -> 13
A9: 캠페인 | B9: =VLOOKUP(A9,$U$2:$Y$28,5,0) -> 8 | U9: 서바이벌 | V9: 5 | W9: 1 | Y9: =V9+W9+X9 -> 6
A10: 미니게임 | B10: =VLOOKUP(A10,$U$2:$Y$28,5,0) -> 6 | U10: 컨트롤 | V10: 3 | W10: 2 | Y10: =V10+W10+X10 -> 5
A11: 디플로메시 | B11: =VLOOKUP(A11,$U$2:$Y$28,5,0) -> 6 | U11: 리듬게임 | V11: 1 | W11: 0 | Y11: =V11+W11+X11 -> 1
A12: 서바이벌 | B12: =VLOOKUP(A12,$U$2:$Y$28,5,0) -> 6 | U12: 퍼즐 | V12: 2 | W12: 0 | Y12: =V12+W12+X12 -> 2
A13: 컨트롤 | B13: =VLOOKUP(A13,$U$2:$Y$28,5,0) -> 5 | U13: 밀리기반 | V13: 1 | W13: 0 | Y13: =V13+W13+X13 -> 1
... A25: 추리 | B25: =VLOOKUP(A25,$U$2:$Y$28,5,0) -> 0 | U25: AOS | V25: 0 | W25: 0 | Y25: =V25+W25+X25 -> 0
A26: 슈팅 | B26: =VLOOKUP(A26,$U$2:$Y$28,5,0) -> 0 | U26: 호환요청 | W26: 9 | Y26: =V26+W26+X26 -> 9
A27: AOS | B27: =VLOOKUP(A27,$U$2:$Y$28,5,0) -> 0 | U27: 레이싱 | V27: 0 | W27: 0 | Y27: =V27+W27+X27 -> 0
A28: 레이싱 | B28: =VLOOKUP(A28,$U$2:$Y$28,5,0) -> 0 | U28: 맞히기 | W28: 61 | Y28: =V28+W28+X28 -> 61

Sheet 2024.09
A1: 장르 | B1: 개수 | V1: 내가만든유즈맵 | W1: 타인제작유즈맵 | X1: 맞히기 | Y1: 총 개수
A2: 맞히기 | B2: =VLOOKUP(A2,$U$2:$Y$28,5,0) -> 58 | U2: 캠페인 | V2: 7 | W2: 0 | Y2: =V2+W2+X2 -> 7
A3: 디펜스 | B3: =VLOOKUP(A3,$U$2:$Y$28,5,0) -> 20 | U3: 디펜스 | V3: 20 | W3: 0 | Y3: =V3+W3+X3 -> 20
A4: 컴까기 | B4: =VLOOKUP(A4,$U$2:$Y$28,5,0) -> 13 | U4: 대전 | V4: 6 | W4: 6 | Y4: =V4+W4+X4 -> 12
A5: 대전 | B5: =VLOOKUP(A5,$U$2:$Y$28,5,0) -> 12 | U5: RPG | V5: 3 | W5: 0 | Y5: =V5+W5+X5 -> 3
A6: 캠페인 | B6: =VLOOKUP(A6,$U$2:$Y$28,5,0) -> 7 | U6: 블러드 | V6: 0 | W6: 2 | Y6: =V6+W6+X6 -> 2
A7: 컨트롤 | B7: =VLOOKUP(A7,$U$2:$Y$28,5,0) -> 7 | U7: 미니게임 | V7: 3 | W7: 1 | Y7: =V7+W7+X7 -> 4
A8: 키우기 | B8: =VLOOKUP(A8,$U$2:$Y$28,5,0) -> 6 | U8: 컴까기 | V8: 9 | W8: 4 | Y8: =V8+W8+X8 -> 13
A9: 디플로메시 | B9: =VLOOKUP(A9,$U$2:$Y$28,5,0) -> 5 | U9: 서바이벌 | V9: 4 | W9: 0 | Y9: =V9+W9+X9 -> 4
A10: 호환요청 | B10: =VLOOKUP(A10,$U$2:$Y$28,5,0) -> 4 | U10: 컨트롤 | V10: 7 | W10: 0 | Y10: =V10+W10+X10 -> 7
A11: 미니게임 | B11: =VLOOKUP(A11,$U$2:$Y$28,5,0) -> 4 | U11: 리듬게임 | V11: 1 | W11: 0 | Y11: =V11+W11+X11 -> 1
A12: 서바이벌 | B12: =VLOOKUP(A12,$U$2:$Y$28,5,0) -> 4 | U12: 퍼즐 | V12: 1 | W12: 0 | Y12: =V12+W12+X12 -> 1
A13: RPG | B13: =VLOOKUP(A13,$U$2:$Y$28,5,0) -> 3 | U13: 밀리기반 | V13: 3 | W13: 0 | Y13: =V13+W13+X13 -> 3
... A27: AOS | B27: =VLOOKUP(A27,$U$2:$Y$28,5,0) -> 0 | U27: 레이싱 | V27: 0 | W27: 0 | Y27: =V27+W27+X27 -> 0
A28: 레이싱 | B28: =VLOOKUP(A28,$U$2:$Y$28,5,0) -> 0 | U28: 맞히기 | V28: 0 | W28: 0 | X28: 58 | Y28: =V28+W28+X28 -> 58

Sheet 2024.10
A1: 장르 | B1: 개수 | V1: 내가만든유즈맵 | W1: 타인제작유즈맵 | X1: 맞히기 | Y1: 총 개수
A2: 맞히기 | B2: =VLOOKUP(A2,$U$2:$Y$28,5,0) -> 60 | U2: 캠페인 | V2: 6 | W2: 1 | Y2: =V2+W2+X2 -> 7
A3: 컴까기 | B3: =VLOOKUP(A3,$U$2:$Y$28,5,0) -> 15 | U3: 디펜스 | V3: 9 | W3: 2 | Y3: =V3+W3+X3 -> 11
A4: 대전 | B4: =VLOOKUP(A4,$U$2:$Y$28,5,0) -> 14 | U4: 대전 | V4: 11 | W4: 3 | Y4: =V4+W4+X4 -> 14
A5: 디펜스 | B5: =VLOOKUP(A5,$U$2:$Y$28,5,0) -> 11 | U5: RPG | V5: 2 | W5: 0 | Y5: =V5+W5+X5 -> 2
A6: 캠페인 | B6: =VLOOKUP(A6,$U$2:$Y$28,5,0) -> 7 | U6: 블러드 | V6: 1 | W6: 0 | Y6: =V6+W6+X6 -> 1
A7: 디플로메시 | B7: =VLOOKUP(A7,$U$2:$Y$28,5,0) -> 5 | U7: 미니게임 | V7: 1 | W7: 0 | Y7: =V7+W7+X7 -> 1
A8: 호환요청 | B8: =VLOOKUP(A8,$U$2:$Y$28,5,0) -> 4 | U8: 컴까기 | V8: 13 | W8: 2 | Y8: =V8+W8+X8 -> 15
A9: 컨트롤 | B9: =VLOOKUP(A9,$U$2:$Y$28,5,0) -> 3 | U9: 서바이벌 | V9: 2 | W9: 0 | Y9: =V9+W9+X9 -> 2
A10: 키우기 | B10: =VLOOKUP(A10,$U$2:$Y$28,5,0) -> 3 | U10: 컨트롤 | V10: 3 | W10: 0 | Y10: =V10+W10+X10 -> 3
A11: 서바이벌 | B11: =VLOOKUP(A11,$U$2:$Y$28,5,0) -> 2 | U11: 리듬게임 | V11: 1 | W11: 0 | Y11: =V11+W11+X11 -> 1
A12: RPG | B12: =VLOOKUP(A12,$U$2:$Y$28,5,0) -> 2 | U12: 퍼즐 | V12: 0 | W12: 0 | Y12: =V12+W12+X12 -> 0
A13: 오펜스 | B13: =VLOOKUP(A13,$U$2:$Y$28,5,0) -> 2 | U13: 밀리기반 | V13: 1 | W13: 0 | Y13: =V13+W13+X13 -> 1
... A27: AOS | B27: =VLOOKUP(A27,$U$2:$Y$28,5,0) -> 0 | U27: 레이싱 | V27: 0 | W27: 0 | Y27: =V27+W27+X27 -> 0
A28: 레이싱 | B28: =VLOOKUP(A28,$U$2:$Y$28,5,0) -> 0 | U28: 맞히기 | V28: 0 | W28: 0 | X28: 60 | Y28: =V28+W28+X28 -> 60

Sheet 2024.11
A1: 장르 | B1: 개수 | V1: 내가만든유즈맵 | W1: 타인제작유즈맵 | X1: 맞히기 | Y1: 총 개수
A2: 맞히기 | B2: =VLOOKUP(A2,$U$2:$Y$28,5,0) -> 52 | U2: 캠페인 | V2: 3 | W2: 3 | Y2: =V2+W2+X2 -> 6
A3: 대전 | B3: =VLOOKUP(A3,$U$2:$Y$28,5,0) -> 16 | U3: 디펜스 | V3: 14 | W3: 1 | Y3: =V3+W3+X3 -> 15
A4: 디펜스 | B4: =VLOOKUP(A4,$U$2:$Y$28,5,0) -> 15 | U4: 대전 | V4: 9 | W4: 7 | Y4: =V4+W4+X4 -> 16
A5: 컴까기 | B5: =VLOOKUP(A5,$U$2:$Y$28,5,0) -> 9 | U5: RPG | V5: 3 | W5: 0 | Y5: =V5+W5+X5 -> 3
A6: 호환요청 | B6: =VLOOKUP(A6,$U$2:$Y$28,5,0) -> 8 | U6: 블러드 | V6: 3 | W6: 0 | Y6: =V6+W6+X6 -> 3
A7: 캠페인 | B7: =VLOOKUP(A7,$U$2:$Y$28,5,0) -> 6 | U7: 미니게임 | V7: 1 | W7: 0 | Y7: =V7+W7+X7 -> 1
A8: 키우기 | B8: =VLOOKUP(A8,$U$2:$Y$28,5,0) -> 6 | U8: 컴까기 | V8: 8 | W8: 1 | Y8: =V8+W8+X8 -> 9
A9: 서바이벌 | B9: =VLOOKUP(A9,$U$2:$Y$28,5,0) -> 6 | U9: 서바이벌 | V9: 6 | W9: 0 | Y9: =V9+W9+X9 -> 6
A10: 컨트롤 | B10: =VLOOKUP(A10,$U$2:$Y$28,5,0) -> 3 | U10: 컨트롤 | V10: 3 | W10: 0 | Y10: =V10+W10+X10 -> 3
A11: RPG | B11: =VLOOKUP(A11,$U$2:$Y$28,5,0) -> 3 | U11: 리듬게임 | V11: 1 | W11: 0 | Y11: =V11+W11+X11 -> 1
A12: 블러드 | B12: =VLOOKUP(A12,$U$2:$Y$28,5,0) -> 3 | U12: 퍼즐 | V12: 0 | W12: 0 | Y12: =V12+W12+X12 -> 0
A13: 디플로메시 | B13: =VLOOKUP(A13,$U$2:$Y$28,5,0) -> 2 | U13: 밀리기반 | V13: 0 | W13: 0 | Y13: =V13+W13+X13 -> 0
... A27: AOS | B27: =VLOOKUP(A27,$U$2:$Y$28,5,0) -> 0 | U27: 레이싱 | V27: 0 | W27: 0 | Y27: =V27+W27+X27 -> 0
A28: 레이싱 | B28: =VLOOKUP(A28,$U$2:$Y$28,5,0) -> 0 | U28: 맞히기 | V28: 0 | W28: 0 | X28: 52 | Y28: =V28+W28+X28 -> 52

Sheet 2024.12
A1: 장르 | B1: 개수 | V1: 내가만든유즈맵 | W1: 타인제작유즈맵 | X1: 맞히기 | Y1: 총 개수
A2: 맞히기 | B2: =VLOOKUP(A2,$U$2:$Y$28,5,0) -> 37 | U2: 캠페인 | V2: 4 | W2: 1 | Y2: =V2+W2+X2 -> 5
A3: 컴까기 | B3: =VLOOKUP(A3,$U$2:$Y$28,5,0) -> 19 | U3: 디펜스 | V3: 11 | W3: 3 | Y3: =V3+W3+X3 -> 14
A4: 디펜스 | B4: =VLOOKUP(A4,$U$2:$Y$28,5,0) -> 14 | U4: 대전 | V4: 6 | W4: 2 | Y4: =V4+W4+X4 -> 8
A5: 대전 | B5: =VLOOKUP(A5,$U$2:$Y$28,5,0) -> 8 | U5: RPG | V5: 4 | W5: 2 | Y5: =V5+W5+X5 -> 6
A6: RPG | B6: =VLOOKUP(A6,$U$2:$Y$28,5,0) -> 6 | U6: 블러드 | V6: 2 | W6: 0 | Y6: =V6+W6+X6 -> 2
A7: 캠페인 | B7: =VLOOKUP(A7,$U$2:$Y$28,5,0) -> 5 | U7: 미니게임 | V7: 2 | W7: 0 | Y7: =V7+W7+X7 -> 2
A8: 서바이벌 | B8: =VLOOKUP(A8,$U$2:$Y$28,5,0) -> 4 | U8: 컴까기 | V8: 18 | W8: 1 | Y8: =V8+W8+X8 -> 19
A9: 어드벤처 | B9: =VLOOKUP(A9,$U$2:$Y$28,5,0) -> 3 | U9: 서바이벌 | V9: 4 | W9: 0 | Y9: =V9+W9+X9 -> 4
A10: 호환요청 | B10: =VLOOKUP(A10,$U$2:$Y$28,5,0) -> 2 | U10: 컨트롤 | V10: 1 | W10: 0 | Y10: =V10+W10+X10 -> 1
A11: 블러드 | B11: =VLOOKUP(A11,$U$2:$Y$28,5,0) -> 2 | U11: 리듬게임 | V11: 0 | W11: 0 | Y11: =V11+W11+X11 -> 0
A12: 공포 | B12: =VLOOKUP(A12,$U$2:$Y$28,5,0) -> 2 | U12: 퍼즐 | V12: 1 | W12: 0 | Y12: =V12+W12+X12 -> 1
A13: 미니게임 | B13: =VLOOKUP(A13,$U$2:$Y$28,5,0) -> 2 | U13: 밀리기반 | V13: 1 | W13: 0 | Y13: =V13+W13+X13 -> 1
... A27: AOS | B27: =VLOOKUP(A27,$U$2:$Y$28,5,0) -> 0 | U27: 레이싱 | V27: 0 | W27: 0 | Y27: =V27+W27+X27 -> 0
A28: 레이싱 | B28: =VLOOKUP(A28,$U$2:$Y$28,5,0) -> 0 | U28: 맞히기 | V28: 0 | W28: 0 | X28: 37 | Y28: =V28+W28+X28 -> 37

Sheet 2025.01
A1: 장르 | B1: 개수 | R1: 내가만든유즈맵 | S1: 타인제작유즈맵 | T1: 맞히기 | U1: 총 개수
A2: 맞히기 | B2: =VLOOKUP(A2,$Q$2:$U$28,5,0) -> 50 | Q2: 캠페인 | R2: 1 | S2: 1 | U2: =R2+S2+T2 -> 2
A3: 디펜스 | B3: =VLOOKUP(A3,$Q$2:$U$28,5,0) -> 13 | Q3: 디펜스 | R3: 13 | S3: 0 | U3: =R3+S3+T3 -> 13
A4: 컴까기 | B4: =VLOOKUP(A4,$Q$2:$U$28,5,0) -> 12 | Q4: 대전 | R4: 9 | S4: 1 | U4: =R4+S4+T4 -> 10
A5: 대전 | B5: =VLOOKUP(A5,$Q$2:$U$28,5,0) -> 10 | Q5: RPG | R5: 2 | S5: 1 | U5: =R5+S5+T5 -> 3
A6: 호환요청 | B6: =VLOOKUP(A6,$Q$2:$U$28,5,0) -> 6 | Q6: 블러드 | R6: 1 | S6: 0 | U6: =R6+S6+T6 -> 1
A7: 기타 | B7: =VLOOKUP(A7,$Q$2:$U$28,5,0) -> 6 | Q7: 미니게임 | R7: 0 | S7: 0 | U7: =R7+S7+T7 -> 0
A8: 서바이벌 | B8: =VLOOKUP(A8,$Q$2:$U$28,5,0) -> 4 | Q8: 컴까기 | R8: 12 | S8: 0 | U8: =R8+S8+T8 -> 12
A9: RPG | B9: =VLOOKUP(A9,$Q$2:$U$28,5,0) -> 3 | Q9: 서바이벌 | R9: 4 | S9: 0 | U9: =R9+S9+T9 -> 4
A10: 어드벤처 | B10: =VLOOKUP(A10,$Q$2:$U$28,5,0) -> 3 | Q10: 컨트롤 | R10: 1 | S10: 0 | U10: =R10+S10+T10 -> 1
A11: 캠페인 | B11: =VLOOKUP(A11,$Q$2:$U$28,5,0) -> 2 | Q11: 리듬게임 | R11: 0 | S11: 0 | U11: =R11+S11+T11 -> 0
A12: 공포 | B12: =VLOOKUP(A12,$Q$2:$U$28,5,0) -> 2 | Q12: 퍼즐 | R12: 2 | S12: 0 | U12: =R12+S12+T12 -> 2
A13: 밀리기반 | B13: =VLOOKUP(A13,$Q$2:$U$28,5,0) -> 2 | Q13: 밀리기반 | R13: 2 | S13: 0 | U13: =R13+S13+T13 -> 2
... A27: 병맛 | B27: =VLOOKUP(A27,$Q$2:$U$28,5,0) -> 0 | Q27: 레이싱 | R27: 0 | S27: 0 | U27: =R27+S27+T27 -> 0
A28: 레이싱 | B28: =VLOOKUP(A28,$Q$2:$U$28,5,0) -> 0 | Q28: 맞히기 | R28: 0 | S28: 0 | T28: 50 | U28: =R28+S28+T28 -> 50

Sheet 2025.02
A1: 장르 | B1: 개수 | R1: 내가만든유즈맵 | S1: 타인제작유즈맵 | T1: 맞히기 | U1: 총 개수
A2: 맞히기 | B2: =VLOOKUP(A2,$Q$2:$U$28,5,0) -> 52 | Q2: 캠페인 | R2: 12 | S2: 1 | U2: =R2+S2+T2 -> 13
A3: 디펜스 | B3: =VLOOKUP(A3,$Q$2:$U$28,5,0) -> 15 | Q3: 디펜스 | R3: 15 | S3: 0 | U3: =R3+S3+T3 -> 15
A4: 캠페인 | B4: =VLOOKUP(A4,$Q$2:$U$28,5,0) -> 13 | Q4: 대전 | R4: 10 | S4: 2 | U4: =R4+S4+T4 -> 12
A5: 대전 | B5: =VLOOKUP(A5,$Q$2:$U$28,5,0) -> 12 | Q5: RPG | R5: 4 | S5: 0 | U5: =R5+S5+T5 -> 4
A6: 서바이벌 | B6: =VLOOKUP(A6,$Q$2:$U$28,5,0) -> 11 | Q6: 블러드 | R6: 0 | S6: 0 | U6: =R6+S6+T6 -> 0
A7: 컴까기 | B7: =VLOOKUP(A7,$Q$2:$U$28,5,0) -> 9 | Q7: 미니게임 | R7: 3 | S7: 0 | U7: =R7+S7+T7 -> 3
A8: 키우기 | B8: =VLOOKUP(A8,$Q$2:$U$28,5,0) -> 5 | Q8: 컴까기 | R8: 9 | S8: 0 | U8: =R8+S8+T8 -> 9
A9: RPG | B9: =VLOOKUP(A9,$Q$2:$U$28,5,0) -> 4 | Q9: 서바이벌 | R9: 10 | S9: 1 | U9: =R9+S9+T9 -> 11
A10: 밀리기반 | B10: =VLOOKUP(A10,$Q$2:$U$28,5,0) -> 3 | Q10: 컨트롤 | R10: 1 | S10: 0 | U10: =R10+S10+T10 -> 1
A11: 미니게임 | B11: =VLOOKUP(A11,$Q$2:$U$28,5,0) -> 3 | Q11: 리듬게임 | R11: 0 | S11: 0 | U11: =R11+S11+T11 -> 0
A12: 호환요청 | B12: =VLOOKUP(A12,$Q$2:$U$28,5,0) -> 2 | Q12: 퍼즐 | R12: 2 | S12: 0 | U12: =R12+S12+T12 -> 2
A13: 기타 | B13: =VLOOKUP(A13,$Q$2:$U$28,5,0) -> 2 | Q13: 밀리기반 | R13: 3 | S13: 0 | U13: =R13+S13+T13 -> 3
... A27: 추리 | B27: =VLOOKUP(A27,$Q$2:$U$28,5,0) -> 0 | Q27: 레이싱 | R27: 1 | S27: 0 | U27: =R27+S27+T27 -> 1
A28: 병맛 | B28: =VLOOKUP(A28,$Q$2:$U$28,5,0) -> 0 | Q28: 맞히기 | T28: 52 | U28: =R28+S28+T28 -> 52

Sheet 2025.03
A1: 장르 | B1: 개수 | R1: 내가만든유즈맵 | S1: 타인제작유즈맵 | T1: 맞히기 | U1: 총 개수
A2: 맞히기 | B2: =VLOOKUP(A2,$Q$2:$U$28,5,0) -> 61 | Q2: 캠페인 | R2: 5 | S2: 2 | U2: =R2+S2+T2 -> 7
A3: 디펜스 | B3: =VLOOKUP(A3,$Q$2:$U$28,5,0) -> 20 | Q3: 디펜스 | R3: 20 | S3: 0 | U3: =R3+S3+T3 -> 20
A4: 대전 | B4: =VLOOKUP(A4,$Q$2:$U$28,5,0) -> 19 | Q4: 대전 | R4: 13 | S4: 6 | U4: =R4+S4+T4 -> 19
A5: 컴까기 | B5: =VLOOKUP(A5,$Q$2:$U$28,5,0) -> 11 | Q5: RPG | R5: 6 | S5: 2 | U5: =R5+S5+T5 -> 8
A6: RPG | B6: =VLOOKUP(A6,$Q$2:$U$28,5,0) -> 8 | Q6: 블러드 | R6: 1 | S6: 1 | U6: =R6+S6+T6 -> 2
A7: 캠페인 | B7: =VLOOKUP(A7,$Q$2:$U$28,5,0) -> 7 | Q7: 미니게임 | R7: 2 | S7: 0 | U7: =R7+S7+T7 -> 2
A8: 서바이벌 | B8: =VLOOKUP(A8,$Q$2:$U$28,5,0) -> 7 | Q8: 컴까기 | R8: 11 | S8: 0 | U8: =R8+S8+T8 -> 11
A9: 키우기 | B9: =VLOOKUP(A9,$Q$2:$U$28,5,0) -> 4 | Q9: 서바이벌 | R9: 7 | S9: 0 | U9: =R9+S9+T9 -> 7
A10: 호환요청 | B10: =VLOOKUP(A10,$Q$2:$U$28,5,0) -> 4 | Q10: 컨트롤 | R10: 1 | S10: 0 | U10: =R10+S10+T10 -> 1
A11: 퍼즐 | B11: =VLOOKUP(A11,$Q$2:$U$28,5,0) -> 3 | Q11: 리듬게임 | R11: 0 | S11: 0 | U11: =R11+S11+T11 -> 0
A12: 어드벤처 | B12: =VLOOKUP(A12,$Q$2:$U$28,5,0) -> 3 | Q12: 퍼즐 | R12: 3 | S12: 0 | U12: =R12+S12+T12 -> 3
A13: 밀리기반 | B13: =VLOOKUP(A13,$Q$2:$U$28,5,0) -> 2 | Q13: 밀리기반 | R13: 2 | S13: 0 | U13: =R13+S13+T13 -> 2
... A27: 추리 | B27: =VLOOKUP(A27,$Q$2:$U$28,5,0) -> 0 | Q27: 레이싱 | R27: 0 | S27: 0 | U27: =R27+S27+T27 -> 0
A28: 병맛 | B28: =VLOOKUP(A28,$Q$2:$U$28,5,0) -> 0 | Q28: 맞히기 | T28: 61 | U28: =R28+S28+T28 -> 61

Sheet 2025.04
A1: 장르 | B1: 개수 | R1: 내가만든유즈맵 | S1: 타인제작유즈맵 | T1: 맞히기 | U1: 총 개수
A2: 맞히기 | B2: =VLOOKUP(A2,$Q$2:$U$28,5,0) -> 44 | Q2: 캠페인 | R2: 1 | S2: 1 | U2: =R2+S2+T2 -> 2
A3: 대전 | B3: =VLOOKUP(A3,$Q$2:$U$28,5,0) -> 12 | Q3: 디펜스 | R3: 8 | S3: 0 | U3: =R3+S3+T3 -> 8
A4: 디펜스 | B4: =VLOOKUP(A4,$Q$2:$U$28,5,0) -> 8 | Q4: 대전 | R4: 9 | S4: 3 | U4: =R4+S4+T4 -> 12
A5: 컴까기 | B5: =VLOOKUP(A5,$Q$2:$U$28,5,0) -> 8 | Q5: RPG | R5: 4 | S5: 2 | U5: =R5+S5+T5 -> 6
A6: RPG | B6: =VLOOKUP(A6,$Q$2:$U$28,5,0) -> 6 | Q6: 블러드 | R6: 0 | S6: 0 | U6: =R6+S6+T6 -> 0
A7: 키우기 | B7: =VLOOKUP(A7,$Q$2:$U$28,5,0) -> 6 | Q7: 미니게임 | R7: 2 | S7: 0 | U7: =R7+S7+T7 -> 2
A8: 호환요청 | B8: =VLOOKUP(A8,$Q$2:$U$28,5,0) -> 6 | Q8: 컴까기 | R8: 7 | S8: 1 | U8: =R8+S8+T8 -> 8
A9: 서바이벌 | B9: =VLOOKUP(A9,$Q$2:$U$28,5,0) -> 3 | Q9: 서바이벌 | R9: 2 | S9: 1 | U9: =R9+S9+T9 -> 3
A10: 퍼즐 | B10: =VLOOKUP(A10,$Q$2:$U$28,5,0) -> 3 | Q10: 컨트롤 | R10: 2 | S10: 0 | U10: =R10+S10+T10 -> 2
A11: 캠페인 | B11: =VLOOKUP(A11,$Q$2:$U$28,5,0) -> 2 | Q11: 리듬게임 | R11: 1 | S11: 0 | U11: =R11+S11+T11 -> 1
A12: 미니게임 | B12: =VLOOKUP(A12,$Q$2:$U$28,5,0) -> 2 | Q12: 퍼즐 | R12: 3 | S12: 0 | U12: =R12+S12+T12 -> 3
A13: 컨트롤 | B13: =VLOOKUP(A13,$Q$2:$U$28,5,0) -> 2 | Q13: 밀리기반 | R13: 1 | S13: 0 | U13: =R13+S13+T13 -> 1
... A27: 추리 | B27: =VLOOKUP(A27,$Q$2:$U$28,5,0) -> 0 | Q27: 레이싱 | R27: 0 | S27: 0 | U27: =R27+S27+T27 -> 0
A28: 병맛 | B28: =VLOOKUP(A28,$Q$2:$U$28,5,0) -> 0 | Q28: 맞히기 | R28: 0 | S28: 0 | T28: 44 | U28: =R28+S28+T28 -> 44

Sheet 2025.05
A1: 장르 | B1: 개수 | R1: 내가만든유즈맵 | S1: 타인제작유즈맵 | T1: 맞히기 | U1: 총 개수
A2: 맞히기 | B2: =VLOOKUP(A2,$Q$2:$U$28,5,0) -> 64 | Q2: 캠페인 | R2: 2 | S2: 1 | U2: =R2+S2+T2 -> 3
A3: 대전 | B3: =VLOOKUP(A3,$Q$2:$U$28,5,0) -> 16 | Q3: 디펜스 | R3: 8 | S3: 0 | U3: =R3+S3+T3 -> 8
A4: RPG | B4: =VLOOKUP(A4,$Q$2:$U$28,5,0) -> 11 | Q4: 대전 | R4: 16 | S4: 0 | U4: =R4+S4+T4 -> 16
A5: 밀리기반 | B5: =VLOOKUP(A5,$Q$2:$U$28,5,0) -> 9 | Q5: RPG | R5: 9 | S5: 2 | U5: =R5+S5+T5 -> 11
A6: 디펜스 | B6: =VLOOKUP(A6,$Q$2:$U$28,5,0) -> 8 | Q6: 블러드 | R6: 0 | S6: 0 | U6: =R6+S6+T6 -> 0
A7: 컴까기 | B7: =VLOOKUP(A7,$Q$2:$U$28,5,0) -> 8 | Q7: 미니게임 | R7: 3 | S7: 0 | U7: =R7+S7+T7 -> 3
A8: 서바이벌 | B8: =VLOOKUP(A8,$Q$2:$U$28,5,0) -> 7 | Q8: 컴까기 | R8: 8 | S8: 0 | U8: =R8+S8+T8 -> 8
A9: 키우기 | B9: =VLOOKUP(A9,$Q$2:$U$28,5,0) -> 4 | Q9: 서바이벌 | R9: 7 | S9: 0 | U9: =R9+S9+T9 -> 7
A10: 캠페인 | B10: =VLOOKUP(A10,$Q$2:$U$28,5,0) -> 3 | Q10: 컨트롤 | R10: 2 | S10: 1 | U10: =R10+S10+T10 -> 3
A11: 미니게임 | B11: =VLOOKUP(A11,$Q$2:$U$28,5,0) -> 3 | Q11: 리듬게임 | R11: 1 | S11: 0 | U11: =R11+S11+T11 -> 1
A12: 컨트롤 | B12: =VLOOKUP(A12,$Q$2:$U$28,5,0) -> 3 | Q12: 퍼즐 | R12: 2 | S12: 0 | U12: =R12+S12+T12 -> 2
A13: 호환요청 | B13: =VLOOKUP(A13,$Q$2:$U$28,5,0) -> 2 | Q13: 밀리기반 | R13: 8 | S13: 1 | U13: =R13+S13+T13 -> 9
... A27: 추리 | B27: =VLOOKUP(A27,$Q$2:$U$28,5,0) -> 0 | Q27: 레이싱 | R27: 0 | S27: 0 | U27: =R27+S27+T27 -> 0
A28: 병맛 | B28: =VLOOKUP(A28,$Q$2:$U$28,5,0) -> 0 | Q28: 맞히기 | R28: 0 | S28: 0 | T28: 64 | U28: =R28+S28+T28 -> 64

Sheet 2025.06
A1: 장르 | B1: 개수 | R1: 내가만든유즈맵 | S1: 타인제작유즈맵 | T1: 맞히기 | U1: 총 개수
A2: 맞히기 | B2: =VLOOKUP(A2,$Q$2:$U$28,5,0) -> 38 | Q2: 캠페인 | R2: 3 | S2: 0 | U2: =R2+S2+T2 -> 3
A3: 대전 | B3: =VLOOKUP(A3,$Q$2:$U$28,5,0) -> 14 | Q3: 디펜스 | R3: 10 | S3: 2 | U3: =R3+S3+T3 -> 12
A4: 서바이벌 | B4: =VLOOKUP(A4,$Q$2:$U$28,5,0) -> 14 | Q4: 대전 | R4: 13 | S4: 1 | U4: =R4+S4+T4 -> 14
A5: 디펜스 | B5: =VLOOKUP(A5,$Q$2:$U$28,5,0) -> 12 | Q5: RPG | R5: 3 | S5: 0 | U5: =R5+S5+T5 -> 3
A6: 컴까기 | B6: =VLOOKUP(A6,$Q$2:$U$28,5,0) -> 7 | Q6: 블러드 | R6: 1 | S6: 0 | U6: =R6+S6+T6 -> 1
A7: 키우기 | B7: =VLOOKUP(A7,$Q$2:$U$28,5,0) -> 4 | Q7: 미니게임 | R7: 2 | S7: 0 | U7: =R7+S7+T7 -> 2
A8: RPG | B8: =VLOOKUP(A8,$Q$2:$U$28,5,0) -> 3 | Q8: 컴까기 | R8: 7 | S8: 0 | U8: =R8+S8+T8 -> 7
A9: 밀리기반 | B9: =VLOOKUP(A9,$Q$2:$U$28,5,0) -> 3 | Q9: 서바이벌 | R9: 14 | S9: 0 | U9: =R9+S9+T9 -> 14
A10: 캠페인 | B10: =VLOOKUP(A10,$Q$2:$U$28,5,0) -> 3 | Q10: 컨트롤 | R10: 3 | S10: 0 | U10: =R10+S10+T10 -> 3
A11: 컨트롤 | B11: =VLOOKUP(A11,$Q$2:$U$28,5,0) -> 3 | Q11: 리듬게임 | R11: 0 | S11: 0 | U11: =R11+S11+T11 -> 0
A12: 호환요청 | B12: =VLOOKUP(A12,$Q$2:$U$28,5,0) -> 3 | Q12: 퍼즐 | R12: 1 | S12: 0 | U12: =R12+S12+T12 -> 1
A13: 미니게임 | B13: =VLOOKUP(A13,$Q$2:$U$28,5,0) -> 2 | Q13: 밀리기반 | R13: 3 | S13: 0 | U13: =R13+S13+T13 -> 3
... A27: 추리 | B27: =VLOOKUP(A27,$Q$2:$U$28,5,0) -> 0 | Q27: 레이싱 | R27: 0 | S27: 0 | U27: =R27+S27+T27 -> 0
A28: 병맛 | B28: =VLOOKUP(A28,$Q$2:$U$28,5,0) -> 0 | Q28: 맞히기 | R28: 0 | S28: 0 | T28: 38 | U28: =R28+S28+T28 -> 38

Sheet 2025.07
A1: 장르 | B1: 개수 | R1: 내가만든유즈맵 | S1: 타인제작유즈맵 | T1: 맞히기 | U1: 총 개수
A2: 맞히기 | B2: =VLOOKUP(A2,$Q$2:$U$28,5,0) -> 44 | Q2: 캠페인 | R2: 3 | S2: 0 | U2: =R2+S2+T2 -> 3
A3: 컴까기 | B3: =VLOOKUP(A3,$Q$2:$U$28,5,0) -> 17 | Q3: 디펜스 | R3: 12 | S3: 1 | U3: =R3+S3+T3 -> 13
A4: 대전 | B4: =VLOOKUP(A4,$Q$2:$U$28,5,0) -> 16 | Q4: 대전 | R4: 16 | S4: 0 | U4: =R4+S4+T4 -> 16
A5: 디펜스 | B5: =VLOOKUP(A5,$Q$2:$U$28,5,0) -> 13 | Q5: RPG | R5: 4 | S5: 1 | U5: =R5+S5+T5 -> 5
A6: 서바이벌 | B6: =VLOOKUP(A6,$Q$2:$U$28,5,0) -> 10 | Q6: 블러드 | R6: 0 | S6: 0 | U6: =R6+S6+T6 -> 0
A7: 키우기 | B7: =VLOOKUP(A7,$Q$2:$U$28,5,0) -> 6 | Q7: 미니게임 | R7: 3 | S7: 0 | U7: =R7+S7+T7 -> 3
A8: 컨트롤 | B8: =VLOOKUP(A8,$Q$2:$U$28,5,0) -> 6 | Q8: 컴까기 | R8: 17 | S8: 0 | U8: =R8+S8+T8 -> 17
A9: RPG | B9: =VLOOKUP(A9,$Q$2:$U$28,5,0) -> 5 | Q9: 서바이벌 | R9: 10 | S9: 0 | U9: =R9+S9+T9 -> 10
A10: 기타 | B10: =VLOOKUP(A10,$Q$2:$U$28,5,0) -> 4 | Q10: 컨트롤 | R10: 6 | S10: 0 | U10: =R10+S10+T10 -> 6
A11: 캠페인 | B11: =VLOOKUP(A11,$Q$2:$U$28,5,0) -> 3 | Q11: 리듬게임 | R11: 0 | S11: 0 | U11: =R11+S11+T11 -> 0
A12: 미니게임 | B12: =VLOOKUP(A12,$Q$2:$U$28,5,0) -> 3 | Q12: 퍼즐 | R12: 1 | S12: 0 | U12: =R12+S12+T12 -> 1
A13: 호환요청 | B13: =VLOOKUP(A13,$Q$2:$U$28,5,0) -> 2 | Q13: 밀리기반 | R13: 0 | S13: 0 | U13: =R13+S13+T13 -> 0
... A27: 영상 | B27: =VLOOKUP(A27,$Q$2:$U$28,5,0) -> 0 | Q27: 레이싱 | R27: 0 | S27: 0 | U27: =R27+S27+T27 -> 0
A28: 병맛 | B28: =VLOOKUP(A28,$Q$2:$U$28,5,0) -> 0 | Q28: 맞히기 | R28: 0 | S28: 0 | T28: 44 | U28: =R28+S28+T28 -> 44

Sheet 2025.08
A1: 장르 | B1: 개수 | R1: 내가만든유즈맵 | S1: 타인제작유즈맵 | T1: 맞히기 | U1: 총 개수
A2: 맞히기 | B2: =VLOOKUP(A2,$Q$2:$U$28,5,0) -> 43 | Q2: 캠페인 | R2: 3 | S2: 0 | U2: =R2+S2+T2 -> 3
A3: 대전 | B3: =VLOOKUP(A3,$Q$2:$U$28,5,0) -> 17 | Q3: 디펜스 | R3: 13 | S3: 1 | U3: =R3+S3+T3 -> 14
A4: 컨트롤 | B4: =VLOOKUP(A4,$Q$2:$U$28,5,0) -> 15 | Q4: 대전 | R4: 16 | S4: 1 | U4: =R4+S4+T4 -> 17
A5: 디펜스 | B5: =VLOOKUP(A5,$Q$2:$U$28,5,0) -> 14 | Q5: RPG | R5: 7 | S5: 1 | U5: =R5+S5+T5 -> 8
A6: 컴까기 | B6: =VLOOKUP(A6,$Q$2:$U$28,5,0) -> 12 | Q6: 블러드 | R6: 0 | S6: 0 | U6: =R6+S6+T6 -> 0
A7: RPG | B7: =VLOOKUP(A7,$Q$2:$U$28,5,0) -> 8 | Q7: 미니게임 | R7: 3 | S7: 0 | U7: =R7+S7+T7 -> 3
A8: 서바이벌 | B8: =VLOOKUP(A8,$Q$2:$U$28,5,0) -> 6 | Q8: 컴까기 | R8: 12 | S8: 0 | U8: =R8+S8+T8 -> 12
A9: 키우기 | B9: =VLOOKUP(A9,$Q$2:$U$28,5,0) -> 4 | Q9: 서바이벌 | R9: 6 | S9: 0 | U9: =R9+S9+T9 -> 6
A10: 기타 | B10: =VLOOKUP(A10,$Q$2:$U$28,5,0) -> 3 | Q10: 컨트롤 | R10: 15 | S10: 0 | U10: =R10+S10+T10 -> 15
A11: 캠페인 | B11: =VLOOKUP(A11,$Q$2:$U$28,5,0) -> 3 | Q11: 리듬게임 | R11: 1 | S11: 0 | U11: =R11+S11+T11 -> 1
A12: 미니게임 | B12: =VLOOKUP(A12,$Q$2:$U$28,5,0) -> 3 | Q12: 퍼즐 | R12: 1 | S12: 0 | U12: =R12+S12+T12 -> 1
A13: 병맛 | B13: =VLOOKUP(A13,$Q$2:$U$28,5,0) -> 2 | Q13: 밀리기반 | R13: 1 | S13: 0 | U13: =R13+S13+T13 -> 1
... A27: 레이싱 | B27: =VLOOKUP(A27,$Q$2:$U$28,5,0) -> 0 | Q27: 레이싱 | R27: 0 | S27: 0 | U27: =R27+S27+T27 -> 0
A28: 영상 | B28: =VLOOKUP(A28,$Q$2:$U$28,5,0) -> 0 | Q28: 맞히기 | R28: 0 | S28: 0 | T28: 43 | U28: =R28+S28+T28 -> 43

Sheet 2025.09
A1: 장르 | B1: 개수 | R1: 내가만든유즈맵 | S1: 타인제작유즈맵 | T1: 맞히기 | U1: 총 개수
A2: 맞히기 | B2: =VLOOKUP(A2,$Q$2:$U$28,5,0) -> 41 | Q2: 캠페인 | R2: 3 | S2: 0 | U2: =R2+S2+T2 -> 3
A3: 대전 | B3: =VLOOKUP(A3,$Q$2:$U$28,5,0) -> 12 | Q3: 디펜스 | R3: 10 | S3: 0 | U3: =R3+S3+T3 -> 10
A4: 디펜스 | B4: =VLOOKUP(A4,$Q$2:$U$28,5,0) -> 10 | Q4: 대전 | R4: 10 | S4: 2 | U4: =R4+S4+T4 -> 12
A5: 컨트롤 | B5: =VLOOKUP(A5,$Q$2:$U$28,5,0) -> 7 | Q5: RPG | R5: 4 | S5: 0 | U5: =R5+S5+T5 -> 4
A6: 컴까기 | B6: =VLOOKUP(A6,$Q$2:$U$28,5,0) -> 5 | Q6: 블러드 | R6: 0 | S6: 0 | U6: =R6+S6+T6 -> 0
A7: 서바이벌 | B7: =VLOOKUP(A7,$Q$2:$U$28,5,0) -> 5 | Q7: 미니게임 | R7: 0 | S7: 0 | U7: =R7+S7+T7 -> 0
A8: RPG | B8: =VLOOKUP(A8,$Q$2:$U$28,5,0) -> 4 | Q8: 컴까기 | R8: 5 | S8: 0 | U8: =R8+S8+T8 -> 5
A9: 기타 | B9: =VLOOKUP(A9,$Q$2:$U$28,5,0) -> 4 | Q9: 서바이벌 | R9: 5 | S9: 0 | U9: =R9+S9+T9 -> 5
A10: 키우기 | B10: =VLOOKUP(A10,$Q$2:$U$28,5,0) -> 3 | Q10: 컨트롤 | R10: 6 | S10: 1 | U10: =R10+S10+T10 -> 7
A11: 캠페인 | B11: =VLOOKUP(A11,$Q$2:$U$28,5,0) -> 3 | Q11: 리듬게임 | R11: 0 | S11: 0 | U11: =R11+S11+T11 -> 0
A12: 호환요청 | B12: =VLOOKUP(A12,$Q$2:$U$28,5,0) -> 2 | Q12: 퍼즐 | R12: 1 | S12: 0 | U12: =R12+S12+T12 -> 1
A13: 퍼즐 | B13: =VLOOKUP(A13,$Q$2:$U$28,5,0) -> 1 | Q13: 밀리기반 | R13: 0 | S13: 0 | U13: =R13+S13+T13 -> 0
... A27: 레이싱 | B27: =VLOOKUP(A27,$Q$2:$U$28,5,0) -> 0 | Q27: 레이싱 | R27: 0 | S27: 0 | U27: =R27+S27+T27 -> 0
A28: 영상 | B28: =VLOOKUP(A28,$Q$2:$U$28,5,0) -> 0 | Q28: 맞히기 | R28: 0 | S28: 0 | T28: 41 | U28: =R28+S28+T28 -> 41

Sheet 2025.10
A1: 장르 | B1: 개수 | R1: 내가만든유즈맵 | S1: 타인제작유즈맵 | T1: 맞히기 | U1: 총 개수
A2: 맞히기 | B2: =VLOOKUP(A2,$Q$2:$U$28,5,0) -> 44 | Q2: 캠페인 | R2: 4 | S2: 2 | U2: =R2+S2+T2 -> 6
A3: 디펜스 | B3: =VLOOKUP(A3,$Q$2:$U$28,5,0) -> 15 | Q3: 디펜스 | R3: 14 | S3: 1 | U3: =R3+S3+T3 -> 15
A4: 컴까기 | B4: =VLOOKUP(A4,$Q$2:$U$28,5,0) -> 13 | Q4: 대전 | R4: 6 | S4: 0 | U4: =R4+S4+T4 -> 6
A5: RPG | B5: =VLOOKUP(A5,$Q$2:$U$28,5,0) -> 7 | Q5: RPG | R5: 5 | S5: 2 | U5: =R5+S5+T5 -> 7
A6: 대전 | B6: =VLOOKUP(A6,$Q$2:$U$28,5,0) -> 6 | Q6: 블러드 | R6: 0 | S6: 0 | U6: =R6+S6+T6 -> 0
A7: 서바이벌 | B7: =VLOOKUP(A7,$Q$2:$U$28,5,0) -> 6 | Q7: 미니게임 | R7: 2 | S7: 0 | U7: =R7+S7+T7 -> 2
A8: 캠페인 | B8: =VLOOKUP(A8,$Q$2:$U$28,5,0) -> 6 | Q8: 컴까기 | R8: 12 | S8: 1 | U8: =R8+S8+T8 -> 13
A9: 컨트롤 | B9: =VLOOKUP(A9,$Q$2:$U$28,5,0) -> 3 | Q9: 서바이벌 | R9: 6 | S9: 0 | U9: =R9+S9+T9 -> 6
A10: 키우기 | B10: =VLOOKUP(A10,$Q$2:$U$28,5,0) -> 3 | Q10: 컨트롤 | R10: 3 | S10: 0 | U10: =R10+S10+T10 -> 3
A11: 퍼즐 | B11: =VLOOKUP(A11,$Q$2:$U$28,5,0) -> 3 | Q11: 리듬게임 | R11: 0 | S11: 0 | U11: =R11+S11+T11 -> 0
A12: 디플로메시 | B12: =VLOOKUP(A12,$Q$2:$U$28,5,0) -> 3 | Q12: 퍼즐 | R12: 3 | S12: 0 | U12: =R12+S12+T12 -> 3
A13: 기타 | B13: =VLOOKUP(A13,$Q$2:$U$28,5,0) -> 2 | Q13: 밀리기반 | R13: 2 | S13: 0 | U13: =R13+S13+T13 -> 2
... A27: 레이싱 | B27: =VLOOKUP(A27,$Q$2:$U$28,5,0) -> 0 | Q27: 레이싱 | R27: 0 | S27: 0 | U27: =R27+S27+T27 -> 0
A28: 영상 | B28: =VLOOKUP(A28,$Q$2:$U$28,5,0) -> 0 | Q28: 맞히기 | R28: 0 | S28: 0 | T28: 44 | U28: =R28+S28+T28 -> 44

Sheet 2025.11
A1: 장르 | B1: 개수 | R1: 내가만든유즈맵 | S1: 타인제작유즈맵 | T1: 맞히기 | U1: 총 개수
A2: 맞히기 | B2: =VLOOKUP(A2,$Q$2:$U$28,5,0) -> 44 | Q2: 캠페인 | R2: 1 | S2: 1 | U2: =R2+S2+T2 -> 2
A3: 컴까기 | B3: =VLOOKUP(A3,$Q$2:$U$28,5,0) -> 10 | Q3: 디펜스 | R3: 8 | S3: 0 | U3: =R3+S3+T3 -> 8
A4: 디펜스 | B4: =VLOOKUP(A4,$Q$2:$U$28,5,0) -> 8 | Q4: 대전 | R4: 3 | S4: 0 | U4: =R4+S4+T4 -> 3
A5: 서바이벌 | B5: =VLOOKUP(A5,$Q$2:$U$28,5,0) -> 5 | Q5: RPG | R5: 1 | S5: 0 | U5: =R5+S5+T5 -> 1
A6: 컨트롤 | B6: =VLOOKUP(A6,$Q$2:$U$28,5,0) -> 5 | Q6: 블러드 | R6: 0 | S6: 1 | U6: =R6+S6+T6 -> 1
A7: 대전 | B7: =VLOOKUP(A7,$Q$2:$U$28,5,0) -> 3 | Q7: 미니게임 | R7: 0 | S7: 0 | U7: =R7+S7+T7 -> 0
A8: 오펜스 | B8: =VLOOKUP(A8,$Q$2:$U$28,5,0) -> 3 | Q8: 컴까기 | R8: 9 | S8: 1 | U8: =R8+S8+T8 -> 10
A9: 캠페인 | B9: =VLOOKUP(A9,$Q$2:$U$28,5,0) -> 2 | Q9: 서바이벌 | R9: 5 | S9: 0 | U9: =R9+S9+T9 -> 5
A10: 기타 | B10: =VLOOKUP(A10,$Q$2:$U$28,5,0) -> 2 | Q10: 컨트롤 | R10: 3 | S10: 2 | U10: =R10+S10+T10 -> 5
A11: 탈출 | B11: =VLOOKUP(A11,$Q$2:$U$28,5,0) -> 2 | Q11: 리듬게임 | R11: 0 | S11: 0 | U11: =R11+S11+T11 -> 0
A12: RPG | B12: =VLOOKUP(A12,$Q$2:$U$28,5,0) -> 1 | Q12: 퍼즐 | R12: 0 | S12: 1 | U12: =R12+S12+T12 -> 1
A13: 퍼즐 | B13: =VLOOKUP(A13,$Q$2:$U$28,5,0) -> 1 | Q13: 밀리기반 | R13: 1 | S13: 0 | U13: =R13+S13+T13 -> 1
... A27: 레이싱 | B27: =VLOOKUP(A27,$Q$2:$U$28,5,0) -> 0 | Q27: 레이싱 | R27: 0 | S27: 0 | U27: =R27+S27+T27 -> 0
A28: 영상 | B28: =VLOOKUP(A28,$Q$2:$U$28,5,0) -> 0 | Q28: 맞히기 | T28: 44 | U28: =R28+S28+T28 -> 44

Sheet 2025.12
A1: 장르 | B1: 개수 | R1: 내가만든유즈맵 | S1: 타인제작유즈맵 | T1: 맞히기 | U1: 총 개수
A2: 맞히기 | B2: =VLOOKUP(A2,$Q$2:$U$28,5,0) -> 60 | Q2: 캠페인 | R2: 7 | S2: 0 | U2: =R2+S2+T2 -> 7
A3: 디펜스 | B3: =VLOOKUP(A3,$Q$2:$U$28,5,0) -> 10 | Q3: 디펜스 | R3: 8 | S3: 2 | U3: =R3+S3+T3 -> 10
A4: 컴까기 | B4: =VLOOKUP(A4,$Q$2:$U$28,5,0) -> 9 | Q4: 대전 | R4: 1 | S4: 1 | U4: =R4+S4+T4 -> 2
A5: 서바이벌 | B5: =VLOOKUP(A5,$Q$2:$U$28,5,0) -> 7 | Q5: RPG | R5: 5 | S5: 1 | U5: =R5+S5+T5 -> 6
A6: 캠페인 | B6: =VLOOKUP(A6,$Q$2:$U$28,5,0) -> 7 | Q6: 블러드 | R6: 0 | S6: 0 | U6: =R6+S6+T6 -> 0
A7: RPG | B7: =VLOOKUP(A7,$Q$2:$U$28,5,0) -> 6 | Q7: 미니게임 | R7: 0 | S7: 0 | U7: =R7+S7+T7 -> 0
A8: 컨트롤 | B8: =VLOOKUP(A8,$Q$2:$U$28,5,0) -> 5 | Q8: 컴까기 | R8: 9 | S8: 0 | U8: =R8+S8+T8 -> 9
A9: 오펜스 | B9: =VLOOKUP(A9,$Q$2:$U$28,5,0) -> 5 | Q9: 서바이벌 | R9: 7 | S9: 0 | U9: =R9+S9+T9 -> 7
A10: 대전 | B10: =VLOOKUP(A10,$Q$2:$U$28,5,0) -> 2 | Q10: 컨트롤 | R10: 4 | S10: 1 | U10: =R10+S10+T10 -> 5
A11: 기타 | B11: =VLOOKUP(A11,$Q$2:$U$28,5,0) -> 2 | Q11: 리듬게임 | R11: 0 | S11: 0 | U11: =R11+S11+T11 -> 0
A12: 밀리기반 | B12: =VLOOKUP(A12,$Q$2:$U$28,5,0) -> 1 | Q12: 퍼즐 | R12: 0 | S12: 0 | U12: =R12+S12+T12 -> 0
A13: 키우기 | B13: =VLOOKUP(A13,$Q$2:$U$28,5,0) -> 1 | Q13: 밀리기반 | R13: 1 | S13: 0 | U13: =R13+S13+T13 -> 1
... A27: 슈팅 | B27: =VLOOKUP(A27,$Q$2:$U$28,5,0) -> 0 | Q27: 레이싱 | R27: 1 | S27: 0 | U27: =R27+S27+T27 -> 1
A28: AOS | B28: =VLOOKUP(A28,$Q$2:$U$28,5,0) -> 0 | Q28: 맞히기 | T28: 60 | U28: =R28+S28+T28 -> 60
R30: =SUM(R2:R27) -> 52 | S30: =SUM(S2:S27) -> 6

Sheet 2026.01
A1: 장르 | B1: 개수 | R1: 내가만든유즈맵 | S1: 타인제작유즈맵 | T1: 맞히기 | U1: 총 개수
A2: 맞히기 | B2: =VLOOKUP(A2,$Q$2:$U$28,5,0) -> 40 | Q2: 캠페인 | R2: 7 | S2: 0 | U2: =R2+S2+T2 -> 7
A3: 디펜스 | B3: =VLOOKUP(A3,$Q$2:$U$28,5,0) -> 9 | Q3: 디펜스 | R3: 7 | S3: 2 | U3: =R3+S3+T3 -> 9
A4: 컴까기 | B4: =VLOOKUP(A4,$Q$2:$U$28,5,0) -> 7 | Q4: 대전 | R4: 1 | S4: 1 | U4: =R4+S4+T4 -> 2
A5: 서바이벌 | B5: =VLOOKUP(A5,$Q$2:$U$28,5,0) -> 7 | Q5: RPG | R5: 5 | S5: 1 | U5: =R5+S5+T5 -> 6
A6: 캠페인 | B6: =VLOOKUP(A6,$Q$2:$U$28,5,0) -> 7 | Q6: 블러드 | R6: 0 | S6: 0 | U6: =R6+S6+T6 -> 0
A7: RPG | B7: =VLOOKUP(A7,$Q$2:$U$28,5,0) -> 6 | Q7: 미니게임 | R7: 0 | S7: 0 | U7: =R7+S7+T7 -> 0
A8: 컨트롤 | B8: =VLOOKUP(A8,$Q$2:$U$28,5,0) -> 5 | Q8: 컴까기 | R8: 7 | S8: 0 | U8: =R8+S8+T8 -> 7
A9: 오펜스 | B9: =VLOOKUP(A9,$Q$2:$U$28,5,0) -> 5 | Q9: 서바이벌 | R9: 7 | S9: 0 | U9: =R9+S9+T9 -> 7
A10: 대전 | B10: =VLOOKUP(A10,$Q$2:$U$28,5,0) -> 2 | Q10: 컨트롤 | R10: 4 | S10: 1 | U10: =R10+S10+T10 -> 5
A11: 기타 | B11: =VLOOKUP(A11,$Q$2:$U$28,5,0) -> 2 | Q11: 리듬게임 | R11: 0 | S11: 0 | U11: =R11+S11+T11 -> 0
A12: 밀리기반 | B12: =VLOOKUP(A12,$Q$2:$U$28,5,0) -> 1 | Q12: 퍼즐 | R12: 0 | S12: 0 | U12: =R12+S12+T12 -> 0
A13: 키우기 | B13: =VLOOKUP(A13,$Q$2:$U$28,5,0) -> 1 | Q13: 밀리기반 | R13: 1 | S13: 0 | U13: =R13+S13+T13 -> 1
... A27: 슈팅 | B27: =VLOOKUP(A27,$Q$2:$U$28,5,0) -> 0 | Q27: 레이싱 | R27: 1 | S27: 0 | U27: =R27+S27+T27 -> 1
A28: AOS | B28: =VLOOKUP(A28,$Q$2:$U$28,5,0) -> 0 | Q28: 맞히기 | R28: 0 | S28: 0 | T28: 40 | U28: =R28+S28+T28 -> 40
R30: =SUM(R2:R28) -> 49 | S30: =SUM(S2:S28) -> 6

Sheet 2026.02
A1: 장르 | B1: 개수 | R1: 내가만든유즈맵 | S1: 타인제작유즈맵 | T1: 맞히기 | U1: 총 개수
A2: 맞히기 | B2: =VLOOKUP(A2,$Q$2:$U$28,5,0) -> 27 | Q2: 캠페인 | R2: 5 | S2: 5 | U2: =R2+S2+T2 -> 10
A3: 디펜스 | B3: =VLOOKUP(A3,$Q$2:$U$28,5,0) -> 12 | Q3: 디펜스 | R3: 12 | S3: 0 | U3: =R3+S3+T3 -> 12
A4: 캠페인 | B4: =VLOOKUP(A4,$Q$2:$U$28,5,0) -> 10 | Q4: 대전 | R4: 10 | S4: 0 | U4: =R4+S4+T4 -> 10
A5: 대전 | B5: =VLOOKUP(A5,$Q$2:$U$28,5,0) -> 10 | Q5: RPG | R5: 1 | S5: 1 | U5: =R5+S5+T5 -> 2
A6: RPG | B6: =VLOOKUP(A6,$Q$2:$U$28,5,0) -> 2 | Q6: 블러드 | R6: 0 | S6: 0 | U6: =R6+S6+T6 -> 0
A7: 키우기 | B7: =VLOOKUP(A7,$Q$2:$U$28,5,0) -> 2 | Q7: 미니게임 | R7: 0 | S7: 0 | U7: =R7+S7+T7 -> 0
A8: 컴까기 | B8: =VLOOKUP(A8,$Q$2:$U$28,5,0) -> 1 | Q8: 컴까기 | R8: 1 | S8: 0 | U8: =R8+S8+T8 -> 1
A9: 서바이벌 | B9: =VLOOKUP(A9,$Q$2:$U$28,5,0) -> 1 | Q9: 서바이벌 | R9: 1 | S9: 0 | U9: =R9+S9+T9 -> 1
A10: 컨트롤 | B10: =VLOOKUP(A10,$Q$2:$U$28,5,0) -> 1 | Q10: 컨트롤 | R10: 1 | S10: 0 | U10: =R10+S10+T10 -> 1
A11: 디플로메시 | B11: =VLOOKUP(A11,$Q$2:$U$28,5,0) -> 1 | Q11: 리듬게임 | R11: 0 | S11: 0 | U11: =R11+S11+T11 -> 0
A12: 어드벤처 | B12: =VLOOKUP(A12,$Q$2:$U$28,5,0) -> 1 | Q12: 퍼즐 | R12: 0 | S12: 0 | U12: =R12+S12+T12 -> 0
A13: 오펜스 | B13: =VLOOKUP(A13,$Q$2:$U$28,5,0) -> 0 | Q13: 밀리기반 | R13: 0 | S13: 0 | U13: =R13+S13+T13 -> 0
... A27: 슈팅 | B27: =VLOOKUP(A27,$Q$2:$U$28,5,0) -> 0 | Q27: 레이싱 | R27: 0 | S27: 0 | U27: =R27+S27+T27 -> 0
A28: AOS | B28: =VLOOKUP(A28,$Q$2:$U$28,5,0) -> 0 | Q28: 맞히기 | R28: 0 | S28: 0 | T28: 27 | U28: =R28+S28+T28 -> 27
R30: =SUM(R2:R28) -> 33 | S30: =SUM(S2:S28) -> 8

Sheet 2026.03
A1: 장르 | B1: 개수 | R1: 내가만든유즈맵 | S1: 타인제작유즈맵 | T1: 맞히기 | U1: 총 개수
A2: 맞히기 | B2: =VLOOKUP(A2,$Q$2:$U$28,5,0) -> 39 | Q2: 캠페인 | R2: 0 | S2: 1 | U2: =R2+S2+T2 -> 1
A3: 디펜스 | B3: =VLOOKUP(A3,$Q$2:$U$28,5,0) -> 7 | Q3: 디펜스 | R3: 7 | S3: 0 | U3: =R3+S3+T3 -> 7
A4: 컴까기 | B4: =VLOOKUP(A4,$Q$2:$U$28,5,0) -> 5 | Q4: 대전 | R4: 2 | S4: 0 | U4: =R4+S4+T4 -> 2
A5: 컨트롤 | B5: =VLOOKUP(A5,$Q$2:$U$28,5,0) -> 4 | Q5: RPG | R5: 3 | S5: 0 | U5: =R5+S5+T5 -> 3
A6: RPG | B6: =VLOOKUP(A6,$Q$2:$U$28,5,0) -> 3 | Q6: 블러드 | R6: 0 | S6: 0 | U6: =R6+S6+T6 -> 0
A7: 서바이벌 | B7: =VLOOKUP(A7,$Q$2:$U$28,5,0) -> 3 | Q7: 미니게임 | R7: 0 | S7: 0 | U7: =R7+S7+T7 -> 0
A8: 기타 | B8: =VLOOKUP(A8,$Q$2:$U$28,5,0) -> 3 | Q8: 컴까기 | R8: 5 | S8: 0 | U8: =R8+S8+T8 -> 5
A9: 대전 | B9: =VLOOKUP(A9,$Q$2:$U$28,5,0) -> 2 | Q9: 서바이벌 | R9: 3 | S9: 0 | U9: =R9+S9+T9 -> 3
A10: 어드벤처 | B10: =VLOOKUP(A10,$Q$2:$U$28,5,0) -> 2 | Q10: 컨트롤 | R10: 4 | S10: 0 | U10: =R10+S10+T10 -> 4
A11: 공포 | B11: =VLOOKUP(A11,$Q$2:$U$28,5,0) -> 2 | Q11: 리듬게임 | R11: 1 | S11: 0 | U11: =R11+S11+T11 -> 1
A12: 퍼즐 | B12: =VLOOKUP(A12,$Q$2:$U$28,5,0) -> 2 | Q12: 퍼즐 | R12: 2 | S12: 0 | U12: =R12+S12+T12 -> 2
A13: 캠페인 | B13: =VLOOKUP(A13,$Q$2:$U$28,5,0) -> 1 | Q13: 밀리기반 | R13: 0 | S13: 0 | U13: =R13+S13+T13 -> 0
... A27: 슈팅 | B27: =VLOOKUP(A27,$Q$2:$U$28,5,0) -> 0 | Q27: 레이싱 | R27: 0 | S27: 0 | U27: =R27+S27+T27 -> 0
A28: AOS | B28: =VLOOKUP(A28,$Q$2:$U$28,5,0) -> 0 | Q28: 맞히기 | R28: 0 | S28: 0 | T28: 39 | U28: =R28+S28+T28 -> 39
R30: =SUM(R2:R28) -> 34 | S30: =SUM(S2:S28) -> 4

Sheet 2026.04
A1: 장르 | B1: 개수 | R1: 내가만든유즈맵 | S1: 타인제작유즈맵 | T1: 맞히기 | U1: 총 개수
A2: 맞히기 | B2: =VLOOKUP(A2,$Q$2:$U$28,5,0) -> 38 | Q2: 캠페인 | R2: 3 | S2: 0 | U2: =R2+S2+T2 -> 3
A3: RPG | B3: =VLOOKUP(A3,$Q$2:$U$28,5,0) -> 13 | Q3: 디펜스 | R3: 5 | S3: 4 | U3: =R3+S3+T3 -> 9
A4: 컨트롤 | B4: =VLOOKUP(A4,$Q$2:$U$28,5,0) -> 11 | Q4: 대전 | R4: 4 | S4: 0 | U4: =R4+S4+T4 -> 4
A5: 디펜스 | B5: =VLOOKUP(A5,$Q$2:$U$28,5,0) -> 9 | Q5: RPG | R5: 3 | S5: 10 | U5: =R5+S5+T5 -> 13
A6: 호환요청 | B6: =VLOOKUP(A6,$Q$2:$U$28,5,0) -> 8 | Q6: 블러드 | R6: 0 | S6: 0 | U6: =R6+S6+T6 -> 0
A7: 퍼즐 | B7: =VLOOKUP(A7,$Q$2:$U$28,5,0) -> 6 | Q7: 미니게임 | R7: 0 | S7: 0 | U7: =R7+S7+T7 -> 0
A8: 서바이벌 | B8: =VLOOKUP(A8,$Q$2:$U$28,5,0) -> 5 | Q8: 컴까기 | R8: 3 | S8: 1 | U8: =R8+S8+T8 -> 4
A9: AOS | B9: =VLOOKUP(A9,$Q$2:$U$28,5,0) -> 5 | Q9: 서바이벌 | R9: 4 | S9: 1 | U9: =R9+S9+T9 -> 5
A10: 컴까기 | B10: =VLOOKUP(A10,$Q$2:$U$28,5,0) -> 4 | Q10: 컨트롤 | R10: 11 | S10: 0 | U10: =R10+S10+T10 -> 11
A11: 기타 | B11: =VLOOKUP(A11,$Q$2:$U$28,5,0) -> 4 | Q11: 리듬게임 | R11: 0 | S11: 0 | U11: =R11+S11+T11 -> 0
A12: 대전 | B12: =VLOOKUP(A12,$Q$2:$U$28,5,0) -> 4 | Q12: 퍼즐 | R12: 6 | S12: 0 | U12: =R12+S12+T12 -> 6
A13: 공포 | B13: =VLOOKUP(A13,$Q$2:$U$28,5,0) -> 4 | Q13: 밀리기반 | R13: 0 | S13: 0 | U13: =R13+S13+T13 -> 0
... A27: 추리 | B27: =VLOOKUP(A27,$Q$2:$U$28,5,0) -> 0 | Q27: 레이싱 | R27: 0 | S27: 0 | U27: =R27+S27+T27 -> 0
A28: 슈팅 | B28: =VLOOKUP(A28,$Q$2:$U$28,5,0) -> 0 | Q28: 맞히기 | R28: 0 | S28: 0 | T28: 38 | U28: =R28+S28+T28 -> 38
R30: =SUM(R2:R28) -> 49 | S30: =SUM(S2:S28) -> 33

Sheet 2026.05
A1: 장르 | B1: 개수 | R1: 내가만든유즈맵 | S1: 타인제작유즈맵 | T1: 맞히기 | U1: 총 개수
A2: 맞히기 | B2: =VLOOKUP(A2,$Q$2:$U$28,5,0) -> 44 | Q2: 캠페인 | R2: 3 | S2: 0 | U2: =R2+S2+T2 -> 3
A3: 디펜스 | B3: =VLOOKUP(A3,$Q$2:$U$28,5,0) -> 9 | Q3: 디펜스 | R3: 8 | S3: 1 | U3: =R3+S3+T3 -> 9
A4: 대전 | B4: =VLOOKUP(A4,$Q$2:$U$28,5,0) -> 9 | Q4: 대전 | R4: 8 | S4: 1 | U4: =R4+S4+T4 -> 9
A5: 컴까기 | B5: =VLOOKUP(A5,$Q$2:$U$28,5,0) -> 6 | Q5: RPG | R5: 2 | S5: 0 | U5: =R5+S5+T5 -> 2
A6: 기타 | B6: =VLOOKUP(A6,$Q$2:$U$28,5,0) -> 6 | Q6: 블러드 | R6: 0 | S6: 0 | U6: =R6+S6+T6 -> 0
A7: 컨트롤 | B7: =VLOOKUP(A7,$Q$2:$U$28,5,0) -> 4 | Q7: 미니게임 | R7: 0 | S7: 0 | U7: =R7+S7+T7 -> 0
A8: 캠페인 | B8: =VLOOKUP(A8,$Q$2:$U$28,5,0) -> 3 | Q8: 컴까기 | R8: 5 | S8: 1 | U8: =R8+S8+T8 -> 6
A9: RPG | B9: =VLOOKUP(A9,$Q$2:$U$28,5,0) -> 2 | Q9: 서바이벌 | R9: 1 | S9: 0 | U9: =R9+S9+T9 -> 1
A10: 오펜스 | B10: =VLOOKUP(A10,$Q$2:$U$28,5,0) -> 2 | Q10: 컨트롤 | R10: 4 | S10: 0 | U10: =R10+S10+T10 -> 4
A11: 호환요청 | B11: =VLOOKUP(A11,$Q$2:$U$28,5,0) -> 1 | Q11: 리듬게임 | R11: 0 | S11: 0 | U11: =R11+S11+T11 -> 0
A12: 퍼즐 | B12: =VLOOKUP(A12,$Q$2:$U$28,5,0) -> 1 | Q12: 퍼즐 | R12: 1 | S12: 0 | U12: =R12+S12+T12 -> 1
A13: 서바이벌 | B13: =VLOOKUP(A13,$Q$2:$U$28,5,0) -> 1 | Q13: 밀리기반 | R13: 1 | S13: 0 | U13: =R13+S13+T13 -> 1
... A27: 미니게임 | B27: =VLOOKUP(A27,$Q$2:$U$28,5,0) -> 0 | Q27: 레이싱 | R27: 0 | S27: 0 | U27: =R27+S27+T27 -> 0
A28: 추리 | B28: =VLOOKUP(A28,$Q$2:$U$28,5,0) -> 0 | Q28: 맞히기 | T28: 44 | U28: =R28+S28+T28 -> 44
R30: =SUM(R2:R28) -> 43 | S30: =SUM(S2:S28) -> 7

Sheet 2026.06
A1: 장르 | B1: 개수 | R1: 내가만든유즈맵 | S1: 타인제작유즈맵 | T1: 맞히기 | U1: 총 개수
A2: 맞히기 | B2: =VLOOKUP(A2,$Q$2:$U$28,5,0) -> 36 | Q2: 캠페인 | R2: 12 | S2: 0 | U2: =R2+S2+T2 -> 12
A3: 컨트롤 | B3: =VLOOKUP(A3,$Q$2:$U$28,5,0) -> 23 | Q3: 디펜스 | R3: 5 | S3: 0 | U3: =R3+S3+T3 -> 5
A4: 캠페인 | B4: =VLOOKUP(A4,$Q$2:$U$28,5,0) -> 12 | Q4: 대전 | R4: 4 | S4: 2 | U4: =R4+S4+T4 -> 6
A5: 대전 | B5: =VLOOKUP(A5,$Q$2:$U$28,5,0) -> 6 | Q5: RPG | R5: 4 | S5: 0 | U5: =R5+S5+T5 -> 4
A6: 디펜스 | B6: =VLOOKUP(A6,$Q$2:$U$28,5,0) -> 5 | Q6: 블러드 | R6: 0 | S6: 0 | U6: =R6+S6+T6 -> 0
A7: 컴까기 | B7: =VLOOKUP(A7,$Q$2:$U$28,5,0) -> 5 | Q7: 미니게임 | R7: 1 | S7: 0 | U7: =R7+S7+T7 -> 1
A8: 기타 | B8: =VLOOKUP(A8,$Q$2:$U$28,5,0) -> 5 | Q8: 컴까기 | R8: 5 | S8: 0 | U8: =R8+S8+T8 -> 5
A9: RPG | B9: =VLOOKUP(A9,$Q$2:$U$28,5,0) -> 4 | Q9: 서바이벌 | R9: 4 | S9: 0 | U9: =R9+S9+T9 -> 4
A10: 서바이벌 | B10: =VLOOKUP(A10,$Q$2:$U$28,5,0) -> 4 | Q10: 컨트롤 | R10: 3 | S10: 20 | U10: =R10+S10+T10 -> 23
A11: AOS | B11: =VLOOKUP(A11,$Q$2:$U$28,5,0) -> 3 | Q11: 리듬게임 | R11: 0 | S11: 0 | U11: =R11+S11+T11 -> 0
A12: 퍼즐 | B12: =VLOOKUP(A12,$Q$2:$U$28,5,0) -> 2 | Q12: 퍼즐 | R12: 2 | S12: 0 | U12: =R12+S12+T12 -> 2
A13: 밀리기반 | B13: =VLOOKUP(A13,$Q$2:$U$28,5,0) -> 2 | Q13: 밀리기반 | R13: 1 | S13: 1 | U13: =R13+S13+T13 -> 2
... A27: 블러드 | B27: =VLOOKUP(A27,$Q$2:$U$28,5,0) -> 0 | Q27: 레이싱 | R27: 0 | S27: 0 | U27: =R27+S27+T27 -> 0
A28: 추리 | B28: =VLOOKUP(A28,$Q$2:$U$28,5,0) -> 0 | Q28: 맞히기 | T28: 36 | U28: =R28+S28+T28 -> 36
R30: =SUM(R2:R28) -> 49 | S30: =SUM(S2:S28) -> 25

Sheet 2026.07
A1: 장르 | B1: 개수 | R1: 내가만든유즈맵 | S1: 타인제작유즈맵 | T1: 맞히기 | U1: 총 개수
A2: 맞히기 | B2: =VLOOKUP(A2,$Q$2:$U$28,5,0) -> 55 | Q2: 캠페인 | R2: 9 | S2: 4 | U2: =R2+S2+T2 -> 13
A3: 캠페인 | B3: =VLOOKUP(A3,$Q$2:$U$28,5,0) -> 13 | Q3: 디펜스 | R3: 7 | S3: 3 | U3: =R3+S3+T3 -> 10
A4: 디펜스 | B4: =VLOOKUP(A4,$Q$2:$U$28,5,0) -> 10 | Q4: 대전 | R4: 6 | S4: 1 | U4: =R4+S4+T4 -> 7
A5: RPG | B5: =VLOOKUP(A5,$Q$2:$U$28,5,0) -> 8 | Q5: RPG | R5: 8 | S5: 0 | U5: =R5+S5+T5 -> 8
A6: 대전 | B6: =VLOOKUP(A6,$Q$2:$U$28,5,0) -> 7 | Q6: 블러드 | R6: 0 | S6: 1 | U6: =R6+S6+T6 -> 1
A7: 슈팅 | B7: =VLOOKUP(A7,$Q$2:$U$28,5,0) -> 4 | Q7: 미니게임 | R7: 0 | S7: 0 | U7: =R7+S7+T7 -> 0
A8: 컨트롤 | B8: =VLOOKUP(A8,$Q$2:$U$28,5,0) -> 3 | Q8: 컴까기 | R8: 0 | S8: 0 | U8: =R8+S8+T8 -> 0
A9: 서바이벌 | B9: =VLOOKUP(A9,$Q$2:$U$28,5,0) -> 2 | Q9: 서바이벌 | R9: 2 | S9: 0 | U9: =R9+S9+T9 -> 2
A10: 호환요청 | B10: =VLOOKUP(A10,$Q$2:$U$28,5,0) -> 2 | Q10: 컨트롤 | R10: 2 | S10: 1 | U10: =R10+S10+T10 -> 3
A11: 어드벤처 | B11: =VLOOKUP(A11,$Q$2:$U$28,5,0) -> 2 | Q11: 리듬게임 | R11: 1 | S11: 0 | U11: =R11+S11+T11 -> 1
A12: 디플로메시 | B12: =VLOOKUP(A12,$Q$2:$U$28,5,0) -> 1 | Q12: 퍼즐 | R12: 0 | S12: 0 | U12: =R12+S12+T12 -> 0
A13: 공포 | B13: =VLOOKUP(A13,$Q$2:$U$28,5,0) -> 1 | Q13: 밀리기반 | R13: 0 | S13: 0 | U13: =R13+S13+T13 -> 0
... A27: 레이싱 | B27: =VLOOKUP(A27,$Q$2:$U$28,5,0) -> 0 | Q27: 레이싱 | R27: 0 | S27: 0 | U27: =R27+S27+T27 -> 0
A28: 추리 | B28: =VLOOKUP(A28,$Q$2:$U$28,5,0) -> 0 | Q28: 맞히기 | T28: 55 | U28: =R28+S28+T28 -> 55
R30: =SUM(R2:R28) -> 42 | S30: =SUM(S2:S28) -> 13

Sheet 2026.08
A1: 장르 | B1: 개수 | R1: 내가만든유즈맵 | S1: 타인제작유즈맵 | T1: 맞히기 | U1: 총 개수
A2: 맞히기 | B2: =VLOOKUP(A2,$Q$2:$U$28,5,0) -> 54 | Q2: 캠페인 | R2: 6 | U2: =R2+S2+T2 -> 6
A3: 대전 | B3: =VLOOKUP(A3,$Q$2:$U$28,5,0) -> 13 | Q3: 디펜스 | R3: 6 | U3: =R3+S3+T3 -> 6
A4: 컨트롤 | B4: =VLOOKUP(A4,$Q$2:$U$28,5,0) -> 8 | Q4: 대전 | R4: 13 | U4: =R4+S4+T4 -> 13
A5: RPG | B5: =VLOOKUP(A5,$Q$2:$U$28,5,0) -> 7 | Q5: RPG | R5: 7 | U5: =R5+S5+T5 -> 7
A6: 캠페인 | B6: =VLOOKUP(A6,$Q$2:$U$28,5,0) -> 6 | Q6: 블러드 | R6: 0 | U6: =R6+S6+T6 -> 0
A7: 디펜스 | B7: =VLOOKUP(A7,$Q$2:$U$28,5,0) -> 6 | Q7: 미니게임 | R7: 0 | U7: =R7+S7+T7 -> 0
A8: 컴까기 | B8: =VLOOKUP(A8,$Q$2:$U$28,5,0) -> 3 | Q8: 컴까기 | R8: 3 | U8: =R8+S8+T8 -> 3
A9: 키우기 | B9: =VLOOKUP(A9,$Q$2:$U$28,5,0) -> 3 | Q9: 서바이벌 | R9: 1 | U9: =R9+S9+T9 -> 1
A10: 어드벤처 | B10: =VLOOKUP(A10,$Q$2:$U$28,5,0) -> 2 | Q10: 컨트롤 | R10: 8 | U10: =R10+S10+T10 -> 8
A11: 레이싱 | B11: =VLOOKUP(A11,$Q$2:$U$28,5,0) -> 2 | Q11: 리듬게임 | R11: 0 | U11: =R11+S11+T11 -> 0
A12: 슈팅 | B12: =VLOOKUP(A12,$Q$2:$U$28,5,0) -> 1 | Q12: 퍼즐 | R12: 1 | U12: =R12+S12+T12 -> 1
A13: 서바이벌 | B13: =VLOOKUP(A13,$Q$2:$U$28,5,0) -> 1 | Q13: 밀리기반 | R13: 0 | U13: =R13+S13+T13 -> 0
... A17: 퍼즐 | B17: =VLOOKUP(A17,$Q$2:$U$28,5,0) -> 1 | Q17: 어드벤처 | R17: 2 | U17: =R17+S17+T17 -> 2
A18: 탈출 | B18: =VLOOKUP(A18,$Q$2:$U$28,5,0) -> 1 | Q18: 공포 | R18: 0 | S18: 1 | U18: =R18+S18+T18 -> 1
A19: 호환요청 | B19: =VLOOKUP(A19,$Q$2:$U$28,5,0) -> 0 | Q19: 영상 | R19: 0 | U19: =R19+S19+T19 -> 0
A20: 리듬게임 | B20: =VLOOKUP(A20,$Q$2:$U$28,5,0) -> 0 | Q20: 탈출 | R20: 1 | U20: =R20+S20+T20 -> 1
A21: 블러드 | B21: =VLOOKUP(A21,$Q$2:$U$28,5,0) -> 0 | Q21: 오펜스 | R21: 0 | U21: =R21+S21+T21 -> 0
A22: AOS | B22: =VLOOKUP(A22,$Q$2:$U$28,5,0) -> 0 | Q22: 병맛 | R22: 0 | U22: =R22+S22+T22 -> 0
A23: 밀리기반 | B23: =VLOOKUP(A23,$Q$2:$U$28,5,0) -> 0 | Q23: 추리 | R23: 0 | U23: =R23+S23+T23 -> 0
A24: 영상 | B24: =VLOOKUP(A24,$Q$2:$U$28,5,0) -> 0 | Q24: 슈팅 | R24: 1 | U24: =R24+S24+T24 -> 1
A25: 미니게임 | B25: =VLOOKUP(A25,$Q$2:$U$28,5,0) -> 0 | Q25: AOS | R25: 0 | U25: =R25+S25+T25 -> 0
A26: 오펜스 | B26: =VLOOKUP(A26,$Q$2:$U$28,5,0) -> 0 | Q26: 호환요청 | R26: 0 | U26: =R26+S26+T26 -> 0
A27: 병맛 | B27: =VLOOKUP(A27,$Q$2:$U$28,5,0) -> 0 | Q27: 레이싱 | R27: 2 | U27: =R27+S27+T27 -> 2
A28: 추리 | B28: =VLOOKUP(A28,$Q$2:$U$28,5,0) -> 0 | Q28: 맞히기 | T28: 54 | U28: =R28+S28+T28 -> 54
R30: =SUM(R2:R28) -> 56 | S30: =SUM(S2:S28) -> 1

Sheet 2026.09
A1: 장르 | B1: 개수 | R1: 내가만든유즈맵 | S1: 타인제작유즈맵 | T1: 맞히기 | U1: 총 개수
A2: 맞히기 | B2: =VLOOKUP(A2,$Q$2:$U$28,5,0) -> 57 | Q2: 캠페인 | R2: 0 | S2: 0 | U2: =R2+S2+T2 -> 0
A3: 디펜스 | B3: =VLOOKUP(A3,$Q$2:$U$28,5,0) -> 11 | Q3: 디펜스 | R3: 10 | S3: 1 | U3: =R3+S3+T3 -> 11
A4: 대전 | B4: =VLOOKUP(A4,$Q$2:$U$28,5,0) -> 9 | Q4: 대전 | R4: 6 | S4: 3 | U4: =R4+S4+T4 -> 9
A5: 컴까기 | B5: =VLOOKUP(A5,$Q$2:$U$28,5,0) -> 7 | Q5: RPG | R5: 6 | S5: 0 | U5: =R5+S5+T5 -> 6
A6: RPG | B6: =VLOOKUP(A6,$Q$2:$U$28,5,0) -> 6 | Q6: 블러드 | R6: 0 | S6: 0 | U6: =R6+S6+T6 -> 0
A7: 서바이벌 | B7: =VLOOKUP(A7,$Q$2:$U$28,5,0) -> 3 | Q7: 미니게임 | R7: 1 | S7: 0 | U7: =R7+S7+T7 -> 1
A8: 공포 | B8: =VLOOKUP(A8,$Q$2:$U$28,5,0) -> 3 | Q8: 컴까기 | R8: 7 | S8: 0 | U8: =R8+S8+T8 -> 7
A9: 컨트롤 | B9: =VLOOKUP(A9,$Q$2:$U$28,5,0) -> 2 | Q9: 서바이벌 | R9: 3 | S9: 0 | U9: =R9+S9+T9 -> 3
A10: 퍼즐 | B10: =VLOOKUP(A10,$Q$2:$U$28,5,0) -> 2 | Q10: 컨트롤 | R10: 2 | S10: 0 | U10: =R10+S10+T10 -> 2
A11: 키우기 | B11: =VLOOKUP(A11,$Q$2:$U$28,5,0) -> 1 | Q11: 리듬게임 | R11: 1 | S11: 0 | U11: =R11+S11+T11 -> 1
A12: 디플로메시 | B12: =VLOOKUP(A12,$Q$2:$U$28,5,0) -> 1 | Q12: 퍼즐 | R12: 2 | S12: 0 | U12: =R12+S12+T12 -> 2
A13: 탈출 | B13: =VLOOKUP(A13,$Q$2:$U$28,5,0) -> 1 | Q13: 밀리기반 | R13: 0 | S13: 0 | U13: =R13+S13+T13 -> 0
... A27: 오펜스 | B27: =VLOOKUP(A27,$Q$2:$U$28,5,0) -> 0 | Q27: 레이싱 | R27: 0 | S27: 0 | U27: =R27+S27+T27 -> 0
A28: 추리 | B28: =VLOOKUP(A28,$Q$2:$U$28,5,0) -> 0 | Q28: 맞히기 | T28: 57 | U28: =R28+S28+T28 -> 57
R30: =SUM(R2:R28) -> 45 | S30: =SUM(S2:S28) -> 4

Sheet TOTAL
A1: 장르 | B1: 전체 총합 | C1: 전체 비율 | D1: 2024 총합 | E1: 2025 총합 | F1: 45200 | G1: 45231 | H1: 45261 | I1: 45292 | J1: 45323 | K1: 45352 | L1: 45383 | M1: 45413 | N1: 45444 | O1: 45474 | P1: 45505 | Q1: 45536 | R1: 45566 | S1: 45597 | T1: 45627 | U1: 45658 | V1: 45689 | W1: 45717 | X1: 45748 | Y1: 45778 | Z1: 45809 | AA1: 45839 | AB1: 45870 | AC1: 45901 | AD1: 45931 | AE1: 45962 | AF1: 45992 | AG1: 46023 | AH1: 46054 | AI1: 46082 | AJ1: 46113 | AK1: 46143 | AL1: 46174 | AM1: 46204 | AN1: 46235 | AO1: 46266 | AP1: 46296 | AQ1: 46327 | AR1: 46357 | AS1: 46388
A2: 맞히기 | B2: =SUM(F2:AS2) -> 1490 | C2: =B2/B$30 -> 0.36681438 | D2: =SUM(I2:T2) -> 580 | E2: =SUM(U2:AF2) -> 585 | F2: =VLOOKUP($A2,'2023.10'!$A$2:$B$26,2,FALSE) -> 64 | G2: =VLOOKUP($A2,'2023.11'!$A$2:$B$26,2,FALSE) -> 36 | H2: =VLOOKUP($A2,'2023.12'!$A$2:$B$26,2,FALSE) -> 37 | I2: =VLOOKUP($A2,'2024.01'!$A$2:$B$26,2,FALSE) -> 47 | J2: =VLOOKUP($A2,'2024.02'!$A$2:$B$26,2,FALSE) -> 29 | K2: =VLOOKUP($A2,'2024.03'!$A$2:$B$26,2,FALSE) -> 57 | L2: =VLOOKUP($A2,'2024.04'!$A$2:$B$26,2,FALSE) -> 41 | M2: =VLOOKUP($A2,'2024.05'!$A$2:$B$27,2,FALSE) -> 49 | N2: =VLOOKUP($A2,'2024.06'!$A$2:$B$27,2,FALSE) -> 41 | O2: =VLOOKUP($A2,'2024.07'!$A$2:$B$27,2,FALSE) -> 48 | P2: =VLOOKUP($A2,'2024.08'!$A$2:$B$28,2,FALSE) -> 61 | Q2: =VLOOKUP($A2,'2024.09'!$A$2:$B$28,2,FALSE) -> 58 | R2: =VLOOKUP($A2,'2024.10'!$A$2:$B$28,2,FALSE) -> 60 | S2: =VLOOKUP($A2,'2024.11'!$A$2:$B$28,2,FALSE) -> 52 | T2: =VLOOKUP($A2,'2024.12'!$A$2:$B$28,2,FALSE) -> 37 | U2: =VLOOKUP($A2,'2025.01'!$A$2:$B$28,2,FALSE) -> 50 | V2: =VLOOKUP($A2,'2025.02'!$A$2:$B$28,2,FALSE) -> 52 | W2: =VLOOKUP($A2,'2025.03'!$A$2:$B$28,2,FALSE) -> 61 | X2: =VLOOKUP($A2,'2025.04'!$A$2:$B$28,2,FALSE) -> 44 | Y2: =VLOOKUP($A2,'2025.05'!$A$2:$B$28,2,FALSE) -> 64 | Z2: =VLOOKUP($A2,'2025.06'!$A$2:$B$28,2,FALSE) -> 38 | AA2: =VLOOKUP($A2,'2025.07'!$A$2:$B$28,2,FALSE) -> 44 | AB2: =VLOOKUP($A2,'2025.08'!$A$2:$B$28,2,FALSE) -> 43 | AC2: =VLOOKUP($A2,'2025.09'!$A$2:$B$28,2,FALSE) -> 41 | AD2: =VLOOKUP($A2,'2025.10'!$A$2:$B$28,2,FALSE) -> 44 | AE2: =VLOOKUP($A2,'2025.11'!$A$2:$B$28,2,FALSE) -> 44 | AF2: =VLOOKUP($A2,'2025.12'!$A$2:$B$28,2,FALSE) -> 60 | AG2: =VLOOKUP($A2,'2026.01'!$A$2:$B$28,2,FALSE) -> 40 | AH2: =VLOOKUP($A2,'2026.02'!$A$2:$B$28,2,FALSE) -> 27 | AI2: =VLOOKUP($A2,'2026.03'!$A$2:$B$28,2,FALSE) -> 39 | AJ2: =VLOOKUP($A2,'2026.04'!$A$2:$B$28,2,FALSE) -> 38 | AK2: =VLOOKUP($A2,'2026.05'!$A$2:$B$28,2,FALSE) -> 44
A3: 디펜스 | B3: =SUM(F3:AS3) -> 402 | C3: =B3/B$30 -> 0.098966027 | D3: =SUM(I3:T3) -> 164 | E3: =SUM(U3:AF3) -> 146 | F3: =VLOOKUP($A3,'2023.10'!$A$2:$B$26,2,FALSE) -> 16 | G3: =VLOOKUP($A3,'2023.11'!$A$2:$B$26,2,FALSE) -> 13 | H3: =VLOOKUP($A3,'2023.12'!$A$2:$B$26,2,FALSE) -> 17 | I3: =VLOOKUP($A3,'2024.01'!$A$2:$B$26,2,FALSE) -> 11 | J3: =VLOOKUP($A3,'2024.02'!$A$2:$B$26,2,FALSE) -> 13 | K3: =VLOOKUP($A3,'2024.03'!$A$2:$B$26,2,FALSE) -> 15 | L3: =VLOOKUP($A3,'2024.04'!$A$2:$B$26,2,FALSE) -> 20 | M3: =VLOOKUP($A3,'2024.05'!$A$2:$B$27,2,FALSE) -> 21 | N3: =VLOOKUP($A3,'2024.06'!$A$2:$B$27,2,FALSE) -> 8 | O3: =VLOOKUP($A3,'2024.07'!$A$2:$B$27,2,FALSE) -> 6 | P3: =VLOOKUP($A3,'2024.08'!$A$2:$B$28,2,FALSE) -> 10 | Q3: =VLOOKUP($A3,'2024.09'!$A$2:$B$28,2,FALSE) -> 20 | R3: =VLOOKUP($A3,'2024.10'!$A$2:$B$28,2,FALSE) -> 11 | S3: =VLOOKUP($A3,'2024.11'!$A$2:$B$28,2,FALSE) -> 15 | T3: =VLOOKUP($A3,'2024.12'!$A$2:$B$28,2,FALSE) -> 14 | U3: =VLOOKUP($A3,'2025.01'!$A$2:$B$28,2,FALSE) -> 13 | V3: =VLOOKUP($A3,'2025.02'!$A$2:$B$28,2,FALSE) -> 15 | W3: =VLOOKUP($A3,'2025.03'!$A$2:$B$28,2,FALSE) -> 20 | X3: =VLOOKUP($A3,'2025.04'!$A$2:$B$28,2,FALSE) -> 8 | Y3: =VLOOKUP($A3,'2025.05'!$A$2:$B$28,2,FALSE) -> 8 | Z3: =VLOOKUP($A3,'2025.06'!$A$2:$B$28,2,FALSE) -> 12 | AA3: =VLOOKUP($A3,'2025.07'!$A$2:$B$28,2,FALSE) -> 13 | AB3: =VLOOKUP($A3,'2025.08'!$A$2:$B$28,2,FALSE) -> 14 | AC3: =VLOOKUP($A3,'2025.09'!$A$2:$B$28,2,FALSE) -> 10 | AD3: =VLOOKUP($A3,'2025.10'!$A$2:$B$28,2,FALSE) -> 15 | AE3: =VLOOKUP($A3,'2025.11'!$A$2:$B$28,2,FALSE) -> 8 | AF3: =VLOOKUP($A3,'2025.12'!$A$2:$B$28,2,FALSE) -> 10 | AG3: =VLOOKUP($A3,'2026.01'!$A$2:$B$28,2,FALSE) -> 9 | AH3: =VLOOKUP($A3,'2026.02'!$A$2:$B$28,2,FALSE) -> 12 | AI3: =VLOOKUP($A3,'2026.03'!$A$2:$B$28,2,FALSE) -> 7 | AJ3: =VLOOKUP($A3,'2026.04'!$A$2:$B$28,2,FALSE) -> 9 | AK3: =VLOOKUP($A3,'2026.05'!$A$2:$B$28,2,FALSE) -> 9
